Workbook
Name Cost: TVM!$I$5:$I$14
Name Durations: TVM!$C$5:$C$14
Name Horizon: TVM!$A$12
Name InfR: TVM!$M$5:$M$64
Name IntR: TVM!$L$5:$L$64
Name maxRes: TVM!$P$5:$P$6
Name mmduration: mm!$L$4:$N$13
Name mmhorizon: mm!$A$11
Name mmkind: mm!$A$2
Name mmmrn: mm!$AC$4:$AC$5
Name mmmrnn: mm!$AF$4:$AF$5
Name mmnmode: mm!$A$8
Name mmnnrr: mm!$A$17
Name mmnrr: mm!$A$14
Name mmntask: mm!$A$5
Name mmpd: mm!$Q$4:$Z$13
Name mmtempk: mm!$AU$6:$AU$65
Name mmtempn: mm!$AP$6:$AP$65
Name mmtempr: mm!$AK$6:$AK$65
Name nActivities: TVM!$A$6
Name nResource: TVM!$A$9
Name Pre: TVM!$U$5:$AD$14
Name ReqRes: TVM!$D$5:$E$14

Sheet TVM
T3: predecessor _ p[j,i]
B4: Activity | C4: duration | D4: R1 | E4: R2 | F4: Consumption R1 Cost | G4: Consumption R2 Cost | H4: Fix Cost | I4: Total Cost Per Day | K4: t | L4: Interest Rate | M4: Inflation Rate | O4: RESOURCE AVAILABILITIES: | P4: max res | S4: j à i | T4: tasks | U4: 1 | V4: 2 | W4: 3 | X4: 4 | Y4: 5 | Z4: 6 | AA4: 7 | AB4: 8 | AC4: 9 | AD4: 10
A5: nActivity | B5: 1 | C5: 2 | D5: 0 | E5: 0 | F5: =D5*2000000 -> 0 | G5: =E5*10000000 -> 0 | H5: 11719756 | I5: =H5+G5+F5 -> 11719756 | K5: 1 | L5: 0.1 | M5: 0.11 | O5: 1 | P5: 13 | T5: 1 | U5: =IF(IFERROR('j309-3'!K2,0)=0,0,1) -> 0 | V5: =IF(IFERROR('j309-3'!L2,0)=0,0,1) -> 1 | W5: =IF(IFERROR('j309-3'!M2,0)=0,0,1) -> 1 | X5: =IF(IFERROR('j309-3'!N2,0)=0,0,1) -> 1 | Y5: =IF(IFERROR('j309-3'!O2,0)=0,0,1) -> 0 | Z5: =IF(IFERROR('j309-3'!P2,0)=0,0,1) -> 0 | AA5: =IF(IFERROR('j309-3'!Q2,0)=0,0,1) -> 0 | AB5: =IF(IFERROR('j309-3'!R2,0)=0,0,1) -> 0 | ... AD5: =IF(IFERROR('j309-3'!T2,0)=0,0,1) -> 0
A6: =COUNT(B5:B50) -> 10 | B6: 2 | C6: 10 | D6: 8 | E6: 0 | F6: =D6*2000000 -> 16000000 | G6: =E6*10000000 -> 0 | H6: 48045345 | I6: =H6+G6+F6 -> 64045345 | K6: 2 | L6: 0.03 | M6: 0.2 | O6: 2 | P6: 17 | T6: 2 | U6: =IF(IFERROR('j309-3'!K3,0)=0,0,1) -> 0 | V6: =IF(IFERROR('j309-3'!L3,0)=0,0,1) -> 0 | W6: =IF(IFERROR('j309-3'!M3,0)=0,0,1) -> 0 | X6: =IF(IFERROR('j309-3'!N3,0)=0,0,1) -> 0 | Y6: =IF(IFERROR('j309-3'!O3,0)=0,0,1) -> 1 | Z6: =IF(IFERROR('j309-3'!P3,0)=0,0,1) -> 0 | AA6: =IF(IFERROR('j309-3'!Q3,0)=0,0,1) -> 0 | AB6: =IF(IFERROR('j309-3'!R3,0)=0,0,1) -> 0 | ... AD6: =IF(IFERROR('j309-3'!T3,0)=0,0,1) -> 0
B7: 3 | C7: 8 | D7: 6 | E7: 3 | F7: =D7*2000000 -> 12000000 | G7: =E7*10000000 -> 30000000 | H7: 41242606 | I7: =H7+G7+F7 -> 83242606 | K7: 3 | L7: 0.18 | M7: 0.17 | T7: 3 | U7: =IF(IFERROR('j309-3'!K4,0)=0,0,1) -> 0 | V7: =IF(IFERROR('j309-3'!L4,0)=0,0,1) -> 0 | W7: =IF(IFERROR('j309-3'!M4,0)=0,0,1) -> 0 | X7: =IF(IFERROR('j309-3'!N4,0)=0,0,1) -> 0 | Y7: =IF(IFERROR('j309-3'!O4,0)=0,0,1) -> 0 | Z7: =IF(IFERROR('j309-3'!P4,0)=0,0,1) -> 1 | AA7: =IF(IFERROR('j309-3'!Q4,0)=0,0,1) -> 0 | AB7: =IF(IFERROR('j309-3'!R4,0)=0,0,1) -> 0 | ... AD7: =IF(IFERROR('j309-3'!T4,0)=0,0,1) -> 1
A8: nResource | B8: 4 | C8: 8 | D8: 7 | E8: 3 | F8: =D8*2000000 -> 14000000 | G8: =E8*10000000 -> 30000000 | H8: 19511002 | I8: =H8+G8+F8 -> 63511002 | K8: 4 | L8: 0.04 | M8: 0.07 | T8: 4 | U8: =IF(IFERROR('j309-3'!K5,0)=0,0,1) -> 0 | V8: =IF(IFERROR('j309-3'!L5,0)=0,0,1) -> 0 | W8: =IF(IFERROR('j309-3'!M5,0)=0,0,1) -> 0 | X8: =IF(IFERROR('j309-3'!N5,0)=0,0,1) -> 0 | Y8: =IF(IFERROR('j309-3'!O5,0)=0,0,1) -> 0 | Z8: =IF(IFERROR('j309-3'!P5,0)=0,0,1) -> 0 | AA8: =IF(IFERROR('j309-3'!Q5,0)=0,0,1) -> 0 | AB8: =IF(IFERROR('j309-3'!R5,0)=0,0,1) -> 0 | ... AD8: =IF(IFERROR('j309-3'!T5,0)=0,0,1) -> 0
A9: =COUNT(O5:O50) -> 2 | B9: 5 | C9: 4 | D9: 7 | E9: 1 | F9: =D9*2000000 -> 14000000 | G9: =E9*10000000 -> 10000000 | H9: 40311538 | I9: =H9+G9+F9 -> 64311538 | K9: 5 | L9: 0.03 | M9: 0.11 | T9: 5 | U9: =IF(IFERROR('j309-3'!K6,0)=0,0,1) -> 0 | V9: =IF(IFERROR('j309-3'!L6,0)=0,0,1) -> 0 | W9: =IF(IFERROR('j309-3'!M6,0)=0,0,1) -> 0 | X9: =IF(IFERROR('j309-3'!N6,0)=0,0,1) -> 0 | Y9: =IF(IFERROR('j309-3'!O6,0)=0,0,1) -> 0 | Z9: =IF(IFERROR('j309-3'!P6,0)=0,0,1) -> 0 | AA9: =IF(IFERROR('j309-3'!Q6,0)=0,0,1) -> 1 | AB9: =IF(IFERROR('j309-3'!R6,0)=0,0,1) -> 0 | ... AD9: =IF(IFERROR('j309-3'!T6,0)=0,0,1) -> 0
B10: 6 | C10: 3 | D10: 6 | E10: 2 | F10: =D10*2000000 -> 12000000 | G10: =E10*10000000 -> 20000000 | H10: 22597259 | I10: =H10+G10+F10 -> 54597259 | K10: 6 | L10: 0.01 | M10: 0.05 | T10: 6 | U10: =IF(IFERROR('j309-3'!K7,0)=0,0,1) -> 0 | V10: =IF(IFERROR('j309-3'!L7,0)=0,0,1) -> 0 | W10: =IF(IFERROR('j309-3'!M7,0)=0,0,1) -> 0 | X10: =IF(IFERROR('j309-3'!N7,0)=0,0,1) -> 0 | Y10: =IF(IFERROR('j309-3'!O7,0)=0,0,1) -> 0 | Z10: =IF(IFERROR('j309-3'!P7,0)=0,0,1) -> 0 | AA10: =IF(IFERROR('j309-3'!Q7,0)=0,0,1) -> 0 | AB10: =IF(IFERROR('j309-3'!R7,0)=0,0,1) -> 1 | ... AD10: =IF(IFERROR('j309-3'!T7,0)=0,0,1) -> 0
A11: Horizon | B11: 7 | C11: 3 | D11: 0 | E11: 1 | F11: =D11*2000000 -> 0 | G11: =E11*10000000 -> 10000000 | H11: 30741489 | I11: =H11+G11+F11 -> 40741489 | K11: 7 | L11: 0.11 | M11: 0.04 | T11: 7 | U11: =IF(IFERROR('j309-3'!K8,0)=0,0,1) -> 0 | V11: =IF(IFERROR('j309-3'!L8,0)=0,0,1) -> 0 | W11: =IF(IFERROR('j309-3'!M8,0)=0,0,1) -> 0 | X11: =IF(IFERROR('j309-3'!N8,0)=0,0,1) -> 0 | Y11: =IF(IFERROR('j309-3'!O8,0)=0,0,1) -> 0 | Z11: =IF(IFERROR('j309-3'!P8,0)=0,0,1) -> 0 | AA11: =IF(IFERROR('j309-3'!Q8,0)=0,0,1) -> 0 | AB11: =IF(IFERROR('j309-3'!R8,0)=0,0,1) -> 0 | ... AD11: =IF(IFERROR('j309-3'!T8,0)=0,0,1) -> 0
A12: =COUNT(K5:K100) -> 60 | B12: 8 | C12: 2 | D12: 8 | E12: 3 | F12: =D12*2000000 -> 16000000 | G12: =E12*10000000 -> 30000000 | H12: 46099644 | I12: =H12+G12+F12 -> 92099644 | K12: 8 | L12: 0.2 | M12: 0.01 | T12: 8 | U12: =IF(IFERROR('j309-3'!K9,0)=0,0,1) -> 0 | V12: =IF(IFERROR('j309-3'!L9,0)=0,0,1) -> 0 | W12: =IF(IFERROR('j309-3'!M9,0)=0,0,1) -> 0 | X12: =IF(IFERROR('j309-3'!N9,0)=0,0,1) -> 0 | Y12: =IF(IFERROR('j309-3'!O9,0)=0,0,1) -> 0 | Z12: =IF(IFERROR('j309-3'!P9,0)=0,0,1) -> 0 | AA12: =IF(IFERROR('j309-3'!Q9,0)=0,0,1) -> 0 | AB12: =IF(IFERROR('j309-3'!R9,0)=0,0,1) -> 0 | ... AD12: =IF(IFERROR('j309-3'!T9,0)=0,0,1) -> 0
B13: 9 | C13: 2 | D13: 8 | E13: 2 | F13: =D13*2000000 -> 16000000 | G13: =E13*10000000 -> 20000000 | H13: 17617383 | I13: =H13+G13+F13 -> 53617383 | K13: 9 | L13: 0.05 | M13: 0.05 | T13: 9 | U13: =IF(IFERROR('j309-3'!K10,0)=0,0,1) -> 0 | V13: =IF(IFERROR('j309-3'!L10,0)=0,0,1) -> 0 | W13: =IF(IFERROR('j309-3'!M10,0)=0,0,1) -> 0 | X13: =IF(IFERROR('j309-3'!N10,0)=0,0,1) -> 0 | Y13: =IF(IFERROR('j309-3'!O10,0)=0,0,1) -> 0 | Z13: =IF(IFERROR('j309-3'!P10,0)=0,0,1) -> 0 | AA13: =IF(IFERROR('j309-3'!Q10,0)=0,0,1) -> 0 | AB13: =IF(IFERROR('j309-3'!R10,0)=0,0,1) -> 0 | ... AD13: =IF(IFERROR('j309-3'!T10,0)=0,0,1) -> 0
A14: duedate | B14: 10 | C14: 4 | D14: 0 | E14: 8 | F14: =D14*2000000 -> 0 | G14: =E14*10000000 -> 80000000 | H14: 21316723 | I14: =H14+G14+F14 -> 1.0131672e+08 | K14: 10 | L14: 0.11 | M14: 0.1 | T14: 10 | U14: =IF(IFERROR('j309-3'!K11,0)=0,0,1) -> 0 | V14: =IF(IFERROR('j309-3'!L11,0)=0,0,1) -> 0 | W14: =IF(IFERROR('j309-3'!M11,0)=0,0,1) -> 0 | X14: =IF(IFERROR('j309-3'!N11,0)=0,0,1) -> 0 | Y14: =IF(IFERROR('j309-3'!O11,0)=0,0,1) -> 0 | Z14: =IF(IFERROR('j309-3'!P11,0)=0,0,1) -> 0 | AA14: =IF(IFERROR('j309-3'!Q11,0)=0,0,1) -> 0 | AB14: =IF(IFERROR('j309-3'!R11,0)=0,0,1) -> 0 | ... AD14: =IF(IFERROR('j309-3'!T11,0)=0,0,1) -> 0
A15: 48 | K15: 11 | L15: 0.18 | M15: 0.06
K16: 12 | L16: 0.19 | M16: 0.1
A17: Tardiness Cost | K17: 13 | L17: 0.07 | M17: 0.1
A18: 24 | K18: 14 | L18: 0.19 | M18: 0.15
K19: 15 | L19: 0.09 | M19: 0.1
A20: Minimum Project Makespan | K20: 16 | L20: 0.14 | M20: 0.12
A21: 48 | K21: 17 | L21: 0.16 | M21: 0.17
K22: 18 | L22: 0.15 | M22: 0.09
K23: 19 | L23: 0.09 | M23: 0.06
K24: 20 | L24: 0.05 | M24: 0.17
K25: 21 | L25: 0.08 | M25: 0.15
K26: 22 | L26: 0.04 | M26: 0.09
K27: 23 | L27: 0.14 | M27: 0.1
K28: 24 | L28: 0.11 | M28: 0.11
K29: 25 | L29: 0.12 | M29: 0.2
K30: 26 | L30: 0.01 | M30: 0.08
K31: 27 | L31: 0.15 | M31: 0.09
K32: 28 | L32: 0.06 | M32: 0.04
K33: 29 | L33: 0.06 | M33: 0.15
... K64: 60 | L64: 0.05 | M64: 0.11

Sheet Sheet2
N3: predecessor _ p[j,i]
B4: Activity | C4: duration | D4: R1 | E4: R2 | F4: R3 | G4: R4 | I4: RESOURCE AVAILABILITIES: | J4: max res | M4: j à i | N4: tasks | O4: 1 | P4: 2 | Q4: 3 | R4: 4 | S4: 5 | T4: 6 | U4: 7 | V4: 8 | W4: 9 | X4: 10 | Y4: 11 | Z4: 12 | AA4: 13 | AB4: 14 | AC4: 15 | AD4: 16 | AE4: 17 | AF4: 18 | AG4: 19 | AH4: 20 | AI4: 21 | AJ4: 22 | AK4: 23 | AL4: 24 | AM4: 25 | AN4: 26 | AO4: 27 | AP4: 28 | AQ4: 29 | AR4: 30 | AS4: 31 | AT4: 32
A5: nActivity | B5: 1 | C5: 2 | D5: 0 | E5: 0 | F5: 0 | G5: 0 | I5: 1 | J5: 13 | N5: 1 | O5: =IF(IFERROR('j309-3'!K2,0)=0,0,1) -> 0 | P5: =IF(IFERROR('j309-3'!L2,0)=0,0,1) -> 1 | Q5: =IF(IFERROR('j309-3'!M2,0)=0,0,1) -> 1 | R5: =IF(IFERROR('j309-3'!N2,0)=0,0,1) -> 1 | S5: =IF(IFERROR('j309-3'!O2,0)=0,0,1) -> 0 | T5: =IF(IFERROR('j309-3'!P2,0)=0,0,1) -> 0 | U5: =IF(IFERROR('j309-3'!Q2,0)=0,0,1) -> 0 | V5: =IF(IFERROR('j309-3'!R2,0)=0,0,1) -> 0 | ... AT5: =IF(IFERROR('j309-3'!AP2,0)=0,0,1) -> 0
A6: =COUNT(B5:B50) -> 32 | B6: 2 | C6: 10 | D6: 8 | E6: 0 | F6: 4 | G6: 4 | I6: 2 | J6: 17 | N6: 2 | O6: =IF(IFERROR('j309-3'!K3,0)=0,0,1) -> 0 | P6: =IF(IFERROR('j309-3'!L3,0)=0,0,1) -> 0 | Q6: =IF(IFERROR('j309-3'!M3,0)=0,0,1) -> 0 | R6: =IF(IFERROR('j309-3'!N3,0)=0,0,1) -> 0 | S6: =IF(IFERROR('j309-3'!O3,0)=0,0,1) -> 1 | T6: =IF(IFERROR('j309-3'!P3,0)=0,0,1) -> 0 | U6: =IF(IFERROR('j309-3'!Q3,0)=0,0,1) -> 0 | V6: =IF(IFERROR('j309-3'!R3,0)=0,0,1) -> 0 | ... AT6: =IF(IFERROR('j309-3'!AP3,0)=0,0,1) -> 0
B7: 3 | C7: 8 | D7: 6 | E7: 3 | F7: 0 | G7: 7 | I7: 3 | J7: 19 | N7: 3 | O7: =IF(IFERROR('j309-3'!K4,0)=0,0,1) -> 0 | P7: =IF(IFERROR('j309-3'!L4,0)=0,0,1) -> 0 | Q7: =IF(IFERROR('j309-3'!M4,0)=0,0,1) -> 0 | R7: =IF(IFERROR('j309-3'!N4,0)=0,0,1) -> 0 | S7: =IF(IFERROR('j309-3'!O4,0)=0,0,1) -> 0 | T7: =IF(IFERROR('j309-3'!P4,0)=0,0,1) -> 1 | U7: =IF(IFERROR('j309-3'!Q4,0)=0,0,1) -> 0 | V7: =IF(IFERROR('j309-3'!R4,0)=0,0,1) -> 0 | ... AT7: =IF(IFERROR('j309-3'!AP4,0)=0,0,1) -> 0
A8: nResource | B8: 4 | C8: 8 | D8: 7 | E8: 3 | F8: 3 | G8: 8 | I8: 4 | J8: 14 | N8: 4 | O8: =IF(IFERROR('j309-3'!K5,0)=0,0,1) -> 0 | P8: =IF(IFERROR('j309-3'!L5,0)=0,0,1) -> 0 | Q8: =IF(IFERROR('j309-3'!M5,0)=0,0,1) -> 0 | R8: =IF(IFERROR('j309-3'!N5,0)=0,0,1) -> 0 | S8: =IF(IFERROR('j309-3'!O5,0)=0,0,1) -> 0 | T8: =IF(IFERROR('j309-3'!P5,0)=0,0,1) -> 0 | U8: =IF(IFERROR('j309-3'!Q5,0)=0,0,1) -> 0 | V8: =IF(IFERROR('j309-3'!R5,0)=0,0,1) -> 0 | ... AT8: =IF(IFERROR('j309-3'!AP5,0)=0,0,1) -> 0
A9: =COUNT(I5:I50) -> 4 | B9: 5 | C9: 4 | D9: 7 | E9: 1 | F9: 6 | G9: 10 | N9: 5 | O9: =IF(IFERROR('j309-3'!K6,0)=0,0,1) -> 0 | P9: =IF(IFERROR('j309-3'!L6,0)=0,0,1) -> 0 | Q9: =IF(IFERROR('j309-3'!M6,0)=0,0,1) -> 0 | R9: =IF(IFERROR('j309-3'!N6,0)=0,0,1) -> 0 | S9: =IF(IFERROR('j309-3'!O6,0)=0,0,1) -> 0 | T9: =IF(IFERROR('j309-3'!P6,0)=0,0,1) -> 0 | U9: =IF(IFERROR('j309-3'!Q6,0)=0,0,1) -> 1 | V9: =IF(IFERROR('j309-3'!R6,0)=0,0,1) -> 0 | ... AT9: =IF(IFERROR('j309-3'!AP6,0)=0,0,1) -> 0
B10: 6 | C10: 3 | D10: 6 | E10: 2 | F10: 0 | G10: 10 | N10: 6 | O10: =IF(IFERROR('j309-3'!K7,0)=0,0,1) -> 0 | P10: =IF(IFERROR('j309-3'!L7,0)=0,0,1) -> 0 | Q10: =IF(IFERROR('j309-3'!M7,0)=0,0,1) -> 0 | R10: =IF(IFERROR('j309-3'!N7,0)=0,0,1) -> 0 | S10: =IF(IFERROR('j309-3'!O7,0)=0,0,1) -> 0 | T10: =IF(IFERROR('j309-3'!P7,0)=0,0,1) -> 0 | U10: =IF(IFERROR('j309-3'!Q7,0)=0,0,1) -> 0 | V10: =IF(IFERROR('j309-3'!R7,0)=0,0,1) -> 1 | ... AT10: =IF(IFERROR('j309-3'!AP7,0)=0,0,1) -> 0
A11: Horizon | B11: 7 | C11: 3 | D11: 0 | E11: 1 | F11: 0 | G11: 3 | N11: 7 | O11: =IF(IFERROR('j309-3'!K8,0)=0,0,1) -> 0 | P11: =IF(IFERROR('j309-3'!L8,0)=0,0,1) -> 0 | Q11: =IF(IFERROR('j309-3'!M8,0)=0,0,1) -> 0 | R11: =IF(IFERROR('j309-3'!N8,0)=0,0,1) -> 0 | S11: =IF(IFERROR('j309-3'!O8,0)=0,0,1) -> 0 | T11: =IF(IFERROR('j309-3'!P8,0)=0,0,1) -> 0 | U11: =IF(IFERROR('j309-3'!Q8,0)=0,0,1) -> 0 | V11: =IF(IFERROR('j309-3'!R8,0)=0,0,1) -> 0 | ... AT11: =IF(IFERROR('j309-3'!AP8,0)=0,0,1) -> 0
A12: 60 | B12: 8 | C12: 2 | D12: 8 | E12: 3 | F12: 5 | G12: 8 | N12: 8 | O12: =IF(IFERROR('j309-3'!K9,0)=0,0,1) -> 0 | P12: =IF(IFERROR('j309-3'!L9,0)=0,0,1) -> 0 | Q12: =IF(IFERROR('j309-3'!M9,0)=0,0,1) -> 0 | R12: =IF(IFERROR('j309-3'!N9,0)=0,0,1) -> 0 | S12: =IF(IFERROR('j309-3'!O9,0)=0,0,1) -> 0 | T12: =IF(IFERROR('j309-3'!P9,0)=0,0,1) -> 0 | U12: =IF(IFERROR('j309-3'!Q9,0)=0,0,1) -> 0 | V12: =IF(IFERROR('j309-3'!R9,0)=0,0,1) -> 0 | ... AT12: =IF(IFERROR('j309-3'!AP9,0)=0,0,1) -> 0
B13: 9 | C13: 2 | D13: 8 | E13: 2 | F13: 1 | G13: 2 | N13: 9 | O13: =IF(IFERROR('j309-3'!K10,0)=0,0,1) -> 0 | P13: =IF(IFERROR('j309-3'!L10,0)=0,0,1) -> 0 | Q13: =IF(IFERROR('j309-3'!M10,0)=0,0,1) -> 0 | R13: =IF(IFERROR('j309-3'!N10,0)=0,0,1) -> 0 | S13: =IF(IFERROR('j309-3'!O10,0)=0,0,1) -> 0 | T13: =IF(IFERROR('j309-3'!P10,0)=0,0,1) -> 0 | U13: =IF(IFERROR('j309-3'!Q10,0)=0,0,1) -> 0 | V13: =IF(IFERROR('j309-3'!R10,0)=0,0,1) -> 0 | ... AT13: =IF(IFERROR('j309-3'!AP10,0)=0,0,1) -> 0
A14: duedate | B14: 10 | C14: 4 | D14: 0 | E14: 8 | F14: 10 | G14: 0 | N14: 10 | O14: =IF(IFERROR('j309-3'!K11,0)=0,0,1) -> 0 | P14: =IF(IFERROR('j309-3'!L11,0)=0,0,1) -> 0 | Q14: =IF(IFERROR('j309-3'!M11,0)=0,0,1) -> 0 | R14: =IF(IFERROR('j309-3'!N11,0)=0,0,1) -> 0 | S14: =IF(IFERROR('j309-3'!O11,0)=0,0,1) -> 0 | T14: =IF(IFERROR('j309-3'!P11,0)=0,0,1) -> 0 | U14: =IF(IFERROR('j309-3'!Q11,0)=0,0,1) -> 0 | V14: =IF(IFERROR('j309-3'!R11,0)=0,0,1) -> 0 | ... AT14: =IF(IFERROR('j309-3'!AP11,0)=0,0,1) -> 0
A15: 48 | B15: 11 | C15: 10 | D15: 0 | E15: 1 | F15: 10 | G15: 0 | N15: 11 | O15: =IF(IFERROR('j309-3'!K12,0)=0,0,1) -> 0 | P15: =IF(IFERROR('j309-3'!L12,0)=0,0,1) -> 0 | Q15: =IF(IFERROR('j309-3'!M12,0)=0,0,1) -> 0 | R15: =IF(IFERROR('j309-3'!N12,0)=0,0,1) -> 0 | S15: =IF(IFERROR('j309-3'!O12,0)=0,0,1) -> 0 | T15: =IF(IFERROR('j309-3'!P12,0)=0,0,1) -> 0 | U15: =IF(IFERROR('j309-3'!Q12,0)=0,0,1) -> 0 | V15: =IF(IFERROR('j309-3'!R12,0)=0,0,1) -> 0 | ... AT15: =IF(IFERROR('j309-3'!AP12,0)=0,0,1) -> 0
B16: 12 | C16: 9 | D16: 0 | E16: 4 | F16: 5 | G16: 0 | N16: 12 | O16: =IF(IFERROR('j309-3'!K13,0)=0,0,1) -> 0 | P16: =IF(IFERROR('j309-3'!L13,0)=0,0,1) -> 0 | Q16: =IF(IFERROR('j309-3'!M13,0)=0,0,1) -> 0 | R16: =IF(IFERROR('j309-3'!N13,0)=0,0,1) -> 0 | S16: =IF(IFERROR('j309-3'!O13,0)=0,0,1) -> 0 | T16: =IF(IFERROR('j309-3'!P13,0)=0,0,1) -> 0 | U16: =IF(IFERROR('j309-3'!Q13,0)=0,0,1) -> 0 | V16: =IF(IFERROR('j309-3'!R13,0)=0,0,1) -> 0 | ... AT16: =IF(IFERROR('j309-3'!AP13,0)=0,0,1) -> 0
A17: Tardiness Cost | B17: 13 | C17: 10 | D17: 3 | E17: 0 | F17: 4 | G17: 8 | N17: 13 | O17: =IF(IFERROR('j309-3'!K14,0)=0,0,1) -> 0 | P17: =IF(IFERROR('j309-3'!L14,0)=0,0,1) -> 0 | Q17: =IF(IFERROR('j309-3'!M14,0)=0,0,1) -> 0 | R17: =IF(IFERROR('j309-3'!N14,0)=0,0,1) -> 0 | S17: =IF(IFERROR('j309-3'!O14,0)=0,0,1) -> 0 | T17: =IF(IFERROR('j309-3'!P14,0)=0,0,1) -> 0 | U17: =IF(IFERROR('j309-3'!Q14,0)=0,0,1) -> 0 | V17: =IF(IFERROR('j309-3'!R14,0)=0,0,1) -> 0 | ... AT17: =IF(IFERROR('j309-3'!AP14,0)=0,0,1) -> 0
A18: 24 | B18: 14 | C18: 9 | D18: 4 | E18: 6 | F18: 9 | G18: 3 | N18: 14 | O18: =IF(IFERROR('j309-3'!K15,0)=0,0,1) -> 0 | P18: =IF(IFERROR('j309-3'!L15,0)=0,0,1) -> 0 | Q18: =IF(IFERROR('j309-3'!M15,0)=0,0,1) -> 0 | R18: =IF(IFERROR('j309-3'!N15,0)=0,0,1) -> 0 | S18: =IF(IFERROR('j309-3'!O15,0)=0,0,1) -> 0 | T18: =IF(IFERROR('j309-3'!P15,0)=0,0,1) -> 0 | U18: =IF(IFERROR('j309-3'!Q15,0)=0,0,1) -> 0 | V18: =IF(IFERROR('j309-3'!R15,0)=0,0,1) -> 0 | ... AT18: =IF(IFERROR('j309-3'!AP15,0)=0,0,1) -> 0
B19: 15 | C19: 10 | D19: 0 | E19: 10 | F19: 7 | G19: 0 | N19: 15 | O19: =IF(IFERROR('j309-3'!K16,0)=0,0,1) -> 0 | P19: =IF(IFERROR('j309-3'!L16,0)=0,0,1) -> 0 | Q19: =IF(IFERROR('j309-3'!M16,0)=0,0,1) -> 0 | R19: =IF(IFERROR('j309-3'!N16,0)=0,0,1) -> 0 | S19: =IF(IFERROR('j309-3'!O16,0)=0,0,1) -> 0 | T19: =IF(IFERROR('j309-3'!P16,0)=0,0,1) -> 0 | U19: =IF(IFERROR('j309-3'!Q16,0)=0,0,1) -> 0 | V19: =IF(IFERROR('j309-3'!R16,0)=0,0,1) -> 0 | ... AT19: =IF(IFERROR('j309-3'!AP16,0)=0,0,1) -> 0
A20: Minimum Project Makespan | B20: 16 | C20: 5 | D20: 6 | E20: 0 | F20: 5 | G20: 0 | N20: 16 | O20: =IF(IFERROR('j309-3'!K17,0)=0,0,1) -> 0 | P20: =IF(IFERROR('j309-3'!L17,0)=0,0,1) -> 0 | Q20: =IF(IFERROR('j309-3'!M17,0)=0,0,1) -> 0 | R20: =IF(IFERROR('j309-3'!N17,0)=0,0,1) -> 0 | S20: =IF(IFERROR('j309-3'!O17,0)=0,0,1) -> 0 | T20: =IF(IFERROR('j309-3'!P17,0)=0,0,1) -> 0 | U20: =IF(IFERROR('j309-3'!Q17,0)=0,0,1) -> 0 | V20: =IF(IFERROR('j309-3'!R17,0)=0,0,1) -> 0 | ... AT20: =IF(IFERROR('j309-3'!AP17,0)=0,0,1) -> 0
A21: 48 | B21: 17 | C21: 2 | D21: 9 | E21: 0 | F21: 8 | G21: 0 | N21: 17 | O21: =IF(IFERROR('j309-3'!K18,0)=0,0,1) -> 0 | P21: =IF(IFERROR('j309-3'!L18,0)=0,0,1) -> 0 | Q21: =IF(IFERROR('j309-3'!M18,0)=0,0,1) -> 0 | R21: =IF(IFERROR('j309-3'!N18,0)=0,0,1) -> 0 | S21: =IF(IFERROR('j309-3'!O18,0)=0,0,1) -> 0 | T21: =IF(IFERROR('j309-3'!P18,0)=0,0,1) -> 0 | U21: =IF(IFERROR('j309-3'!Q18,0)=0,0,1) -> 0 | V21: =IF(IFERROR('j309-3'!R18,0)=0,0,1) -> 0 | ... AT21: =IF(IFERROR('j309-3'!AP18,0)=0,0,1) -> 0
B22: 18 | C22: 2 | D22: 1 | E22: 10 | F22: 4 | G22: 9 | N22: 18 | O22: =IF(IFERROR('j309-3'!K19,0)=0,0,1) -> 0 | P22: =IF(IFERROR('j309-3'!L19,0)=0,0,1) -> 0 | Q22: =IF(IFERROR('j309-3'!M19,0)=0,0,1) -> 0 | R22: =IF(IFERROR('j309-3'!N19,0)=0,0,1) -> 0 | S22: =IF(IFERROR('j309-3'!O19,0)=0,0,1) -> 0 | T22: =IF(IFERROR('j309-3'!P19,0)=0,0,1) -> 0 | U22: =IF(IFERROR('j309-3'!Q19,0)=0,0,1) -> 0 | V22: =IF(IFERROR('j309-3'!R19,0)=0,0,1) -> 0 | ... AT22: =IF(IFERROR('j309-3'!AP19,0)=0,0,1) -> 0
B23: 19 | C23: 3 | D23: 7 | E23: 5 | F23: 3 | G23: 0 | N23: 19 | O23: =IF(IFERROR('j309-3'!K20,0)=0,0,1) -> 0 | P23: =IF(IFERROR('j309-3'!L20,0)=0,0,1) -> 0 | Q23: =IF(IFERROR('j309-3'!M20,0)=0,0,1) -> 0 | R23: =IF(IFERROR('j309-3'!N20,0)=0,0,1) -> 0 | S23: =IF(IFERROR('j309-3'!O20,0)=0,0,1) -> 0 | T23: =IF(IFERROR('j309-3'!P20,0)=0,0,1) -> 0 | U23: =IF(IFERROR('j309-3'!Q20,0)=0,0,1) -> 0 | V23: =IF(IFERROR('j309-3'!R20,0)=0,0,1) -> 0 | ... AT23: =IF(IFERROR('j309-3'!AP20,0)=0,0,1) -> 0
B24: 20 | C24: 3 | D24: 7 | E24: 6 | F24: 4 | G24: 9 | N24: 20 | O24: =IF(IFERROR('j309-3'!K21,0)=0,0,1) -> 0 | P24: =IF(IFERROR('j309-3'!L21,0)=0,0,1) -> 0 | Q24: =IF(IFERROR('j309-3'!M21,0)=0,0,1) -> 0 | R24: =IF(IFERROR('j309-3'!N21,0)=0,0,1) -> 0 | S24: =IF(IFERROR('j309-3'!O21,0)=0,0,1) -> 0 | T24: =IF(IFERROR('j309-3'!P21,0)=0,0,1) -> 0 | U24: =IF(IFERROR('j309-3'!Q21,0)=0,0,1) -> 0 | V24: =IF(IFERROR('j309-3'!R21,0)=0,0,1) -> 0 | ... AT24: =IF(IFERROR('j309-3'!AP21,0)=0,0,1) -> 0
B25: 21 | C25: 5 | D25: 4 | E25: 8 | F25: 9 | G25: 0 | N25: 21 | O25: =IF(IFERROR('j309-3'!K22,0)=0,0,1) -> 0 | P25: =IF(IFERROR('j309-3'!L22,0)=0,0,1) -> 0 | Q25: =IF(IFERROR('j309-3'!M22,0)=0,0,1) -> 0 | R25: =IF(IFERROR('j309-3'!N22,0)=0,0,1) -> 0 | S25: =IF(IFERROR('j309-3'!O22,0)=0,0,1) -> 0 | T25: =IF(IFERROR('j309-3'!P22,0)=0,0,1) -> 0 | U25: =IF(IFERROR('j309-3'!Q22,0)=0,0,1) -> 0 | V25: =IF(IFERROR('j309-3'!R22,0)=0,0,1) -> 0 | ... AT25: =IF(IFERROR('j309-3'!AP22,0)=0,0,1) -> 0
B26: 22 | C26: 2 | D26: 4 | E26: 7 | F26: 9 | G26: 8 | N26: 22 | O26: =IF(IFERROR('j309-3'!K23,0)=0,0,1) -> 0 | P26: =IF(IFERROR('j309-3'!L23,0)=0,0,1) -> 0 | Q26: =IF(IFERROR('j309-3'!M23,0)=0,0,1) -> 0 | R26: =IF(IFERROR('j309-3'!N23,0)=0,0,1) -> 0 | S26: =IF(IFERROR('j309-3'!O23,0)=0,0,1) -> 0 | T26: =IF(IFERROR('j309-3'!P23,0)=0,0,1) -> 0 | U26: =IF(IFERROR('j309-3'!Q23,0)=0,0,1) -> 0 | V26: =IF(IFERROR('j309-3'!R23,0)=0,0,1) -> 0 | ... AT26: =IF(IFERROR('j309-3'!AP23,0)=0,0,1) -> 0
B27: 23 | C27: 7 | D27: 0 | E27: 9 | F27: 0 | G27: 6 | N27: 23 | O27: =IF(IFERROR('j309-3'!K24,0)=0,0,1) -> 0 | P27: =IF(IFERROR('j309-3'!L24,0)=0,0,1) -> 0 | Q27: =IF(IFERROR('j309-3'!M24,0)=0,0,1) -> 0 | R27: =IF(IFERROR('j309-3'!N24,0)=0,0,1) -> 0 | S27: =IF(IFERROR('j309-3'!O24,0)=0,0,1) -> 0 | T27: =IF(IFERROR('j309-3'!P24,0)=0,0,1) -> 0 | U27: =IF(IFERROR('j309-3'!Q24,0)=0,0,1) -> 0 | V27: =IF(IFERROR('j309-3'!R24,0)=0,0,1) -> 0 | ... AT27: =IF(IFERROR('j309-3'!AP24,0)=0,0,1) -> 0
B28: 24 | C28: 7 | D28: 1 | E28: 10 | F28: 10 | G28: 0 | N28: 24 | O28: =IF(IFERROR('j309-3'!K25,0)=0,0,1) -> 0 | P28: =IF(IFERROR('j309-3'!L25,0)=0,0,1) -> 0 | Q28: =IF(IFERROR('j309-3'!M25,0)=0,0,1) -> 0 | R28: =IF(IFERROR('j309-3'!N25,0)=0,0,1) -> 0 | S28: =IF(IFERROR('j309-3'!O25,0)=0,0,1) -> 0 | T28: =IF(IFERROR('j309-3'!P25,0)=0,0,1) -> 0 | U28: =IF(IFERROR('j309-3'!Q25,0)=0,0,1) -> 0 | V28: =IF(IFERROR('j309-3'!R25,0)=0,0,1) -> 0 | ... AT28: =IF(IFERROR('j309-3'!AP25,0)=0,0,1) -> 0
B29: 25 | C29: 4 | D29: 0 | E29: 4 | F29: 7 | G29: 9 | N29: 25 | O29: =IF(IFERROR('j309-3'!K26,0)=0,0,1) -> 0 | P29: =IF(IFERROR('j309-3'!L26,0)=0,0,1) -> 0 | Q29: =IF(IFERROR('j309-3'!M26,0)=0,0,1) -> 0 | R29: =IF(IFERROR('j309-3'!N26,0)=0,0,1) -> 0 | S29: =IF(IFERROR('j309-3'!O26,0)=0,0,1) -> 0 | T29: =IF(IFERROR('j309-3'!P26,0)=0,0,1) -> 0 | U29: =IF(IFERROR('j309-3'!Q26,0)=0,0,1) -> 0 | V29: =IF(IFERROR('j309-3'!R26,0)=0,0,1) -> 0 | ... AT29: =IF(IFERROR('j309-3'!AP26,0)=0,0,1) -> 0
B30: 26 | C30: 7 | D30: 6 | E30: 0 | F30: 1 | G30: 1 | N30: 26 | O30: =IF(IFERROR('j309-3'!K27,0)=0,0,1) -> 0 | P30: =IF(IFERROR('j309-3'!L27,0)=0,0,1) -> 0 | Q30: =IF(IFERROR('j309-3'!M27,0)=0,0,1) -> 0 | R30: =IF(IFERROR('j309-3'!N27,0)=0,0,1) -> 0 | S30: =IF(IFERROR('j309-3'!O27,0)=0,0,1) -> 0 | T30: =IF(IFERROR('j309-3'!P27,0)=0,0,1) -> 0 | U30: =IF(IFERROR('j309-3'!Q27,0)=0,0,1) -> 0 | V30: =IF(IFERROR('j309-3'!R27,0)=0,0,1) -> 0 | ... AT30: =IF(IFERROR('j309-3'!AP27,0)=0,0,1) -> 0
B31: 27 | C31: 6 | D31: 1 | E31: 8 | F31: 8 | G31: 10 | N31: 27 | O31: =IF(IFERROR('j309-3'!K28,0)=0,0,1) -> 0 | P31: =IF(IFERROR('j309-3'!L28,0)=0,0,1) -> 0 | Q31: =IF(IFERROR('j309-3'!M28,0)=0,0,1) -> 0 | R31: =IF(IFERROR('j309-3'!N28,0)=0,0,1) -> 0 | S31: =IF(IFERROR('j309-3'!O28,0)=0,0,1) -> 0 | T31: =IF(IFERROR('j309-3'!P28,0)=0,0,1) -> 0 | U31: =IF(IFERROR('j309-3'!Q28,0)=0,0,1) -> 0 | V31: =IF(IFERROR('j309-3'!R28,0)=0,0,1) -> 0 | ... AT31: =IF(IFERROR('j309-3'!AP28,0)=0,0,1) -> 0
B32: 28 | C32: 5 | D32: 7 | E32: 4 | F32: 8 | G32: 0 | N32: 28 | O32: =IF(IFERROR('j309-3'!K29,0)=0,0,1) -> 0 | P32: =IF(IFERROR('j309-3'!L29,0)=0,0,1) -> 0 | Q32: =IF(IFERROR('j309-3'!M29,0)=0,0,1) -> 0 | R32: =IF(IFERROR('j309-3'!N29,0)=0,0,1) -> 0 | S32: =IF(IFERROR('j309-3'!O29,0)=0,0,1) -> 0 | T32: =IF(IFERROR('j309-3'!P29,0)=0,0,1) -> 0 | U32: =IF(IFERROR('j309-3'!Q29,0)=0,0,1) -> 0 | V32: =IF(IFERROR('j309-3'!R29,0)=0,0,1) -> 0 | ... AT32: =IF(IFERROR('j309-3'!AP29,0)=0,0,1) -> 0
B33: 29 | C33: 3 | D33: 0 | E33: 7 | F33: 10 | G33: 9 | N33: 29 | O33: =IF(IFERROR('j309-3'!K30,0)=0,0,1) -> 0 | P33: =IF(IFERROR('j309-3'!L30,0)=0,0,1) -> 0 | Q33: =IF(IFERROR('j309-3'!M30,0)=0,0,1) -> 0 | R33: =IF(IFERROR('j309-3'!N30,0)=0,0,1) -> 0 | S33: =IF(IFERROR('j309-3'!O30,0)=0,0,1) -> 0 | T33: =IF(IFERROR('j309-3'!P30,0)=0,0,1) -> 0 | U33: =IF(IFERROR('j309-3'!Q30,0)=0,0,1) -> 0 | V33: =IF(IFERROR('j309-3'!R30,0)=0,0,1) -> 0 | ... AT33: =IF(IFERROR('j309-3'!AP30,0)=0,0,1) -> 1
... B36: 32 | C36: 2 | D36: 0 | E36: 0 | F36: 0 | G36: 0 | N36: 32 | O36: =IF(IFERROR('j309-3'!K33,0)=0,0,1) -> 0 | P36: =IF(IFERROR('j309-3'!L33,0)=0,0,1) -> 0 | Q36: =IF(IFERROR('j309-3'!M33,0)=0,0,1) -> 0 | R36: =IF(IFERROR('j309-3'!N33,0)=0,0,1) -> 0 | S36: =IF(IFERROR('j309-3'!O33,0)=0,0,1) -> 0 | T36: =IF(IFERROR('j309-3'!P33,0)=0,0,1) -> 0 | U36: =IF(IFERROR('j309-3'!Q33,0)=0,0,1) -> 0 | V36: =IF(IFERROR('j309-3'!R33,0)=0,0,1) -> 0 | ... AT36: =IF(IFERROR('j309-3'!AP33,0)=0,0,1) -> 0

Sheet j309-3
D1: jobnr. | E1: successors | K1: 1 | L1: 2 | M1: 3 | N1: 4 | O1: 5 | P1: 6 | Q1: 7 | R1: 8 | S1: 9 | T1: 10 | U1: 11 | V1: 12 | W1: 13 | X1: 14 | Y1: 15 | Z1: 16 | AA1: 17 | AB1: 18 | AC1: 19 | AD1: 20 | AE1: 21 | AF1: 22 | AG1: 23 | AH1: 24 | AI1: 25 | AJ1: 26 | AK1: 27 | AL1: 28 | AM1: 29 | AN1: 30 | AO1: 31 | AP1: 32
D2: 1 | E2: 2 | F2: 3 | G2: 4 | J2: 1 | K2: =HLOOKUP(K1,$E2:$G2,1,FALSE) -> #N/A | L2: =HLOOKUP(L1,$E2:$G2,1,FALSE) -> 2 | M2: =HLOOKUP(M1,$E2:$G2,1,FALSE) -> 3 | N2: =HLOOKUP(N1,$E2:$G2,1,FALSE) -> 4 | O2: =HLOOKUP(O1,$E2:$G2,1,FALSE) -> #N/A | P2: =HLOOKUP(P1,$E2:$G2,1,FALSE) -> #N/A | Q2: =HLOOKUP(Q1,$E2:$G2,1,FALSE) -> #N/A | R2: =HLOOKUP(R1,$E2:$G2,1,FALSE) -> #N/A | ... AP2: =HLOOKUP(AP1,$E2:$G2,1,FALSE) -> #N/A
D3: 2 | E3: 5 | F3: 17 | G3: 25 | J3: 2 | K3: =HLOOKUP(K$1,$E3:$G3,1,FALSE) -> #N/A | L3: =HLOOKUP(L$1,$E3:$G3,1,FALSE) -> #N/A | M3: =HLOOKUP(M$1,$E3:$G3,1,FALSE) -> #N/A | N3: =HLOOKUP(N$1,$E3:$G3,1,FALSE) -> #N/A | O3: =HLOOKUP(O$1,$E3:$G3,1,FALSE) -> 5 | P3: =HLOOKUP(P$1,$E3:$G3,1,FALSE) -> #N/A | Q3: =HLOOKUP(Q$1,$E3:$G3,1,FALSE) -> #N/A | R3: =HLOOKUP(R$1,$E3:$G3,1,FALSE) -> #N/A | ... AP3: =HLOOKUP(AP$1,$E3:$G3,1,FALSE) -> #N/A
D4: 3 | E4: 6 | F4: 9 | G4: 10 | J4: 3 | K4: =HLOOKUP(K$1,$E4:$G4,1,FALSE) -> #N/A | L4: =HLOOKUP(L$1,$E4:$G4,1,FALSE) -> #N/A | M4: =HLOOKUP(M$1,$E4:$G4,1,FALSE) -> #N/A | N4: =HLOOKUP(N$1,$E4:$G4,1,FALSE) -> #N/A | O4: =HLOOKUP(O$1,$E4:$G4,1,FALSE) -> #N/A | P4: =HLOOKUP(P$1,$E4:$G4,1,FALSE) -> 6 | Q4: =HLOOKUP(Q$1,$E4:$G4,1,FALSE) -> #N/A | R4: =HLOOKUP(R$1,$E4:$G4,1,FALSE) -> #N/A | ... AP4: =HLOOKUP(AP$1,$E4:$G4,1,FALSE) -> #N/A
D5: 4 | E5: 17 | J5: 4 | K5: =HLOOKUP(K$1,$E5:$G5,1,FALSE) -> #N/A | L5: =HLOOKUP(L$1,$E5:$G5,1,FALSE) -> #N/A | M5: =HLOOKUP(M$1,$E5:$G5,1,FALSE) -> #N/A | N5: =HLOOKUP(N$1,$E5:$G5,1,FALSE) -> #N/A | O5: =HLOOKUP(O$1,$E5:$G5,1,FALSE) -> #N/A | P5: =HLOOKUP(P$1,$E5:$G5,1,FALSE) -> #N/A | Q5: =HLOOKUP(Q$1,$E5:$G5,1,FALSE) -> #N/A | R5: =HLOOKUP(R$1,$E5:$G5,1,FALSE) -> #N/A | ... AP5: =HLOOKUP(AP$1,$E5:$G5,1,FALSE) -> #N/A
D6: 5 | E6: 7 | F6: 29 | J6: 5 | K6: =HLOOKUP(K$1,$E6:$G6,1,FALSE) -> #N/A | L6: =HLOOKUP(L$1,$E6:$G6,1,FALSE) -> #N/A | M6: =HLOOKUP(M$1,$E6:$G6,1,FALSE) -> #N/A | N6: =HLOOKUP(N$1,$E6:$G6,1,FALSE) -> #N/A | O6: =HLOOKUP(O$1,$E6:$G6,1,FALSE) -> #N/A | P6: =HLOOKUP(P$1,$E6:$G6,1,FALSE) -> #N/A | Q6: =HLOOKUP(Q$1,$E6:$G6,1,FALSE) -> 7 | R6: =HLOOKUP(R$1,$E6:$G6,1,FALSE) -> #N/A | ... AP6: =HLOOKUP(AP$1,$E6:$G6,1,FALSE) -> #N/A
D7: 6 | E7: 8 | F7: 11 | G7: 15 | J7: 6 | K7: =HLOOKUP(K$1,$E7:$G7,1,FALSE) -> #N/A | L7: =HLOOKUP(L$1,$E7:$G7,1,FALSE) -> #N/A | M7: =HLOOKUP(M$1,$E7:$G7,1,FALSE) -> #N/A | N7: =HLOOKUP(N$1,$E7:$G7,1,FALSE) -> #N/A | O7: =HLOOKUP(O$1,$E7:$G7,1,FALSE) -> #N/A | P7: =HLOOKUP(P$1,$E7:$G7,1,FALSE) -> #N/A | Q7: =HLOOKUP(Q$1,$E7:$G7,1,FALSE) -> #N/A | R7: =HLOOKUP(R$1,$E7:$G7,1,FALSE) -> 8 | ... AP7: =HLOOKUP(AP$1,$E7:$G7,1,FALSE) -> #N/A
D8: 7 | E8: 13 | J8: 7 | K8: =HLOOKUP(K$1,$E8:$G8,1,FALSE) -> #N/A | L8: =HLOOKUP(L$1,$E8:$G8,1,FALSE) -> #N/A | M8: =HLOOKUP(M$1,$E8:$G8,1,FALSE) -> #N/A | N8: =HLOOKUP(N$1,$E8:$G8,1,FALSE) -> #N/A | O8: =HLOOKUP(O$1,$E8:$G8,1,FALSE) -> #N/A | P8: =HLOOKUP(P$1,$E8:$G8,1,FALSE) -> #N/A | Q8: =HLOOKUP(Q$1,$E8:$G8,1,FALSE) -> #N/A | R8: =HLOOKUP(R$1,$E8:$G8,1,FALSE) -> #N/A | ... AP8: =HLOOKUP(AP$1,$E8:$G8,1,FALSE) -> #N/A
D9: 8 | E9: 27 | J9: 8 | K9: =HLOOKUP(K$1,$E9:$G9,1,FALSE) -> #N/A | L9: =HLOOKUP(L$1,$E9:$G9,1,FALSE) -> #N/A | M9: =HLOOKUP(M$1,$E9:$G9,1,FALSE) -> #N/A | N9: =HLOOKUP(N$1,$E9:$G9,1,FALSE) -> #N/A | O9: =HLOOKUP(O$1,$E9:$G9,1,FALSE) -> #N/A | P9: =HLOOKUP(P$1,$E9:$G9,1,FALSE) -> #N/A | Q9: =HLOOKUP(Q$1,$E9:$G9,1,FALSE) -> #N/A | R9: =HLOOKUP(R$1,$E9:$G9,1,FALSE) -> #N/A | ... AP9: =HLOOKUP(AP$1,$E9:$G9,1,FALSE) -> #N/A
D10: 9 | E10: 18 | F10: 21 | G10: 30 | J10: 9 | K10: =HLOOKUP(K$1,$E10:$G10,1,FALSE) -> #N/A | L10: =HLOOKUP(L$1,$E10:$G10,1,FALSE) -> #N/A | M10: =HLOOKUP(M$1,$E10:$G10,1,FALSE) -> #N/A | N10: =HLOOKUP(N$1,$E10:$G10,1,FALSE) -> #N/A | O10: =HLOOKUP(O$1,$E10:$G10,1,FALSE) -> #N/A | P10: =HLOOKUP(P$1,$E10:$G10,1,FALSE) -> #N/A | Q10: =HLOOKUP(Q$1,$E10:$G10,1,FALSE) -> #N/A | R10: =HLOOKUP(R$1,$E10:$G10,1,FALSE) -> #N/A | ... AP10: =HLOOKUP(AP$1,$E10:$G10,1,FALSE) -> #N/A
D11: 10 | E11: 12 | F11: 14 | G11: 19 | J11: 10 | K11: =HLOOKUP(K$1,$E11:$G11,1,FALSE) -> #N/A | L11: =HLOOKUP(L$1,$E11:$G11,1,FALSE) -> #N/A | M11: =HLOOKUP(M$1,$E11:$G11,1,FALSE) -> #N/A | N11: =HLOOKUP(N$1,$E11:$G11,1,FALSE) -> #N/A | O11: =HLOOKUP(O$1,$E11:$G11,1,FALSE) -> #N/A | P11: =HLOOKUP(P$1,$E11:$G11,1,FALSE) -> #N/A | Q11: =HLOOKUP(Q$1,$E11:$G11,1,FALSE) -> #N/A | R11: =HLOOKUP(R$1,$E11:$G11,1,FALSE) -> #N/A | ... AP11: =HLOOKUP(AP$1,$E11:$G11,1,FALSE) -> #N/A
D12: 11 | E12: 22 | J12: 11 | K12: =HLOOKUP(K$1,$E12:$G12,1,FALSE) -> #N/A | L12: =HLOOKUP(L$1,$E12:$G12,1,FALSE) -> #N/A | M12: =HLOOKUP(M$1,$E12:$G12,1,FALSE) -> #N/A | N12: =HLOOKUP(N$1,$E12:$G12,1,FALSE) -> #N/A | O12: =HLOOKUP(O$1,$E12:$G12,1,FALSE) -> #N/A | P12: =HLOOKUP(P$1,$E12:$G12,1,FALSE) -> #N/A | Q12: =HLOOKUP(Q$1,$E12:$G12,1,FALSE) -> #N/A | R12: =HLOOKUP(R$1,$E12:$G12,1,FALSE) -> #N/A | ... AP12: =HLOOKUP(AP$1,$E12:$G12,1,FALSE) -> #N/A
D13: 12 | E13: 16 | F13: 22 | J13: 12 | K13: =HLOOKUP(K$1,$E13:$G13,1,FALSE) -> #N/A | L13: =HLOOKUP(L$1,$E13:$G13,1,FALSE) -> #N/A | M13: =HLOOKUP(M$1,$E13:$G13,1,FALSE) -> #N/A | N13: =HLOOKUP(N$1,$E13:$G13,1,FALSE) -> #N/A | O13: =HLOOKUP(O$1,$E13:$G13,1,FALSE) -> #N/A | P13: =HLOOKUP(P$1,$E13:$G13,1,FALSE) -> #N/A | Q13: =HLOOKUP(Q$1,$E13:$G13,1,FALSE) -> #N/A | R13: =HLOOKUP(R$1,$E13:$G13,1,FALSE) -> #N/A | ... AP13: =HLOOKUP(AP$1,$E13:$G13,1,FALSE) -> #N/A
D14: 13 | E14: 24 | F14: 31 | J14: 13 | K14: =HLOOKUP(K$1,$E14:$G14,1,FALSE) -> #N/A | L14: =HLOOKUP(L$1,$E14:$G14,1,FALSE) -> #N/A | M14: =HLOOKUP(M$1,$E14:$G14,1,FALSE) -> #N/A | N14: =HLOOKUP(N$1,$E14:$G14,1,FALSE) -> #N/A | O14: =HLOOKUP(O$1,$E14:$G14,1,FALSE) -> #N/A | P14: =HLOOKUP(P$1,$E14:$G14,1,FALSE) -> #N/A | Q14: =HLOOKUP(Q$1,$E14:$G14,1,FALSE) -> #N/A | R14: =HLOOKUP(R$1,$E14:$G14,1,FALSE) -> #N/A | ... AP14: =HLOOKUP(AP$1,$E14:$G14,1,FALSE) -> #N/A
D15: 14 | E15: 25 | F15: 27 | J15: 14 | K15: =HLOOKUP(K$1,$E15:$G15,1,FALSE) -> #N/A | L15: =HLOOKUP(L$1,$E15:$G15,1,FALSE) -> #N/A | M15: =HLOOKUP(M$1,$E15:$G15,1,FALSE) -> #N/A | N15: =HLOOKUP(N$1,$E15:$G15,1,FALSE) -> #N/A | O15: =HLOOKUP(O$1,$E15:$G15,1,FALSE) -> #N/A | P15: =HLOOKUP(P$1,$E15:$G15,1,FALSE) -> #N/A | Q15: =HLOOKUP(Q$1,$E15:$G15,1,FALSE) -> #N/A | R15: =HLOOKUP(R$1,$E15:$G15,1,FALSE) -> #N/A | ... AP15: =HLOOKUP(AP$1,$E15:$G15,1,FALSE) -> #N/A
D16: 15 | E16: 19 | J16: 15 | K16: =HLOOKUP(K$1,$E16:$G16,1,FALSE) -> #N/A | L16: =HLOOKUP(L$1,$E16:$G16,1,FALSE) -> #N/A | M16: =HLOOKUP(M$1,$E16:$G16,1,FALSE) -> #N/A | N16: =HLOOKUP(N$1,$E16:$G16,1,FALSE) -> #N/A | O16: =HLOOKUP(O$1,$E16:$G16,1,FALSE) -> #N/A | P16: =HLOOKUP(P$1,$E16:$G16,1,FALSE) -> #N/A | Q16: =HLOOKUP(Q$1,$E16:$G16,1,FALSE) -> #N/A | R16: =HLOOKUP(R$1,$E16:$G16,1,FALSE) -> #N/A | ... AP16: =HLOOKUP(AP$1,$E16:$G16,1,FALSE) -> #N/A
D17: 16 | E17: 20 | J17: 16 | K17: =HLOOKUP(K$1,$E17:$G17,1,FALSE) -> #N/A | L17: =HLOOKUP(L$1,$E17:$G17,1,FALSE) -> #N/A | M17: =HLOOKUP(M$1,$E17:$G17,1,FALSE) -> #N/A | N17: =HLOOKUP(N$1,$E17:$G17,1,FALSE) -> #N/A | O17: =HLOOKUP(O$1,$E17:$G17,1,FALSE) -> #N/A | P17: =HLOOKUP(P$1,$E17:$G17,1,FALSE) -> #N/A | Q17: =HLOOKUP(Q$1,$E17:$G17,1,FALSE) -> #N/A | R17: =HLOOKUP(R$1,$E17:$G17,1,FALSE) -> #N/A | ... AP17: =HLOOKUP(AP$1,$E17:$G17,1,FALSE) -> #N/A
D18: 17 | E18: 18 | J18: 17 | K18: =HLOOKUP(K$1,$E18:$G18,1,FALSE) -> #N/A | L18: =HLOOKUP(L$1,$E18:$G18,1,FALSE) -> #N/A | M18: =HLOOKUP(M$1,$E18:$G18,1,FALSE) -> #N/A | N18: =HLOOKUP(N$1,$E18:$G18,1,FALSE) -> #N/A | O18: =HLOOKUP(O$1,$E18:$G18,1,FALSE) -> #N/A | P18: =HLOOKUP(P$1,$E18:$G18,1,FALSE) -> #N/A | Q18: =HLOOKUP(Q$1,$E18:$G18,1,FALSE) -> #N/A | R18: =HLOOKUP(R$1,$E18:$G18,1,FALSE) -> #N/A | ... AP18: =HLOOKUP(AP$1,$E18:$G18,1,FALSE) -> #N/A
D19: 18 | E19: 31 | J19: 18 | K19: =HLOOKUP(K$1,$E19:$G19,1,FALSE) -> #N/A | L19: =HLOOKUP(L$1,$E19:$G19,1,FALSE) -> #N/A | M19: =HLOOKUP(M$1,$E19:$G19,1,FALSE) -> #N/A | N19: =HLOOKUP(N$1,$E19:$G19,1,FALSE) -> #N/A | O19: =HLOOKUP(O$1,$E19:$G19,1,FALSE) -> #N/A | P19: =HLOOKUP(P$1,$E19:$G19,1,FALSE) -> #N/A | Q19: =HLOOKUP(Q$1,$E19:$G19,1,FALSE) -> #N/A | R19: =HLOOKUP(R$1,$E19:$G19,1,FALSE) -> #N/A | ... AP19: =HLOOKUP(AP$1,$E19:$G19,1,FALSE) -> #N/A
D20: 19 | E20: 22 | J20: 19 | K20: =HLOOKUP(K$1,$E20:$G20,1,FALSE) -> #N/A | L20: =HLOOKUP(L$1,$E20:$G20,1,FALSE) -> #N/A | M20: =HLOOKUP(M$1,$E20:$G20,1,FALSE) -> #N/A | N20: =HLOOKUP(N$1,$E20:$G20,1,FALSE) -> #N/A | O20: =HLOOKUP(O$1,$E20:$G20,1,FALSE) -> #N/A | P20: =HLOOKUP(P$1,$E20:$G20,1,FALSE) -> #N/A | Q20: =HLOOKUP(Q$1,$E20:$G20,1,FALSE) -> #N/A | R20: =HLOOKUP(R$1,$E20:$G20,1,FALSE) -> #N/A | ... AP20: =HLOOKUP(AP$1,$E20:$G20,1,FALSE) -> #N/A
D21: 20 | E21: 23 | J21: 20 | K21: =HLOOKUP(K$1,$E21:$G21,1,FALSE) -> #N/A | L21: =HLOOKUP(L$1,$E21:$G21,1,FALSE) -> #N/A | M21: =HLOOKUP(M$1,$E21:$G21,1,FALSE) -> #N/A | N21: =HLOOKUP(N$1,$E21:$G21,1,FALSE) -> #N/A | O21: =HLOOKUP(O$1,$E21:$G21,1,FALSE) -> #N/A | P21: =HLOOKUP(P$1,$E21:$G21,1,FALSE) -> #N/A | Q21: =HLOOKUP(Q$1,$E21:$G21,1,FALSE) -> #N/A | R21: =HLOOKUP(R$1,$E21:$G21,1,FALSE) -> #N/A | ... AP21: =HLOOKUP(AP$1,$E21:$G21,1,FALSE) -> #N/A
D22: 21 | E22: 26 | J22: 21 | K22: =HLOOKUP(K$1,$E22:$G22,1,FALSE) -> #N/A | L22: =HLOOKUP(L$1,$E22:$G22,1,FALSE) -> #N/A | M22: =HLOOKUP(M$1,$E22:$G22,1,FALSE) -> #N/A | N22: =HLOOKUP(N$1,$E22:$G22,1,FALSE) -> #N/A | O22: =HLOOKUP(O$1,$E22:$G22,1,FALSE) -> #N/A | P22: =HLOOKUP(P$1,$E22:$G22,1,FALSE) -> #N/A | Q22: =HLOOKUP(Q$1,$E22:$G22,1,FALSE) -> #N/A | R22: =HLOOKUP(R$1,$E22:$G22,1,FALSE) -> #N/A | ... AP22: =HLOOKUP(AP$1,$E22:$G22,1,FALSE) -> #N/A
D23: 22 | E23: 28 | J23: 22 | K23: =HLOOKUP(K$1,$E23:$G23,1,FALSE) -> #N/A | L23: =HLOOKUP(L$1,$E23:$G23,1,FALSE) -> #N/A | M23: =HLOOKUP(M$1,$E23:$G23,1,FALSE) -> #N/A | N23: =HLOOKUP(N$1,$E23:$G23,1,FALSE) -> #N/A | O23: =HLOOKUP(O$1,$E23:$G23,1,FALSE) -> #N/A | P23: =HLOOKUP(P$1,$E23:$G23,1,FALSE) -> #N/A | Q23: =HLOOKUP(Q$1,$E23:$G23,1,FALSE) -> #N/A | R23: =HLOOKUP(R$1,$E23:$G23,1,FALSE) -> #N/A | ... AP23: =HLOOKUP(AP$1,$E23:$G23,1,FALSE) -> #N/A
D24: 23 | E24: 26 | J24: 23 | K24: =HLOOKUP(K$1,$E24:$G24,1,FALSE) -> #N/A | L24: =HLOOKUP(L$1,$E24:$G24,1,FALSE) -> #N/A | M24: =HLOOKUP(M$1,$E24:$G24,1,FALSE) -> #N/A | N24: =HLOOKUP(N$1,$E24:$G24,1,FALSE) -> #N/A | O24: =HLOOKUP(O$1,$E24:$G24,1,FALSE) -> #N/A | P24: =HLOOKUP(P$1,$E24:$G24,1,FALSE) -> #N/A | Q24: =HLOOKUP(Q$1,$E24:$G24,1,FALSE) -> #N/A | R24: =HLOOKUP(R$1,$E24:$G24,1,FALSE) -> #N/A | ... AP24: =HLOOKUP(AP$1,$E24:$G24,1,FALSE) -> #N/A
D25: 24 | E25: 27 | J25: 24 | K25: =HLOOKUP(K$1,$E25:$G25,1,FALSE) -> #N/A | L25: =HLOOKUP(L$1,$E25:$G25,1,FALSE) -> #N/A | M25: =HLOOKUP(M$1,$E25:$G25,1,FALSE) -> #N/A | N25: =HLOOKUP(N$1,$E25:$G25,1,FALSE) -> #N/A | O25: =HLOOKUP(O$1,$E25:$G25,1,FALSE) -> #N/A | P25: =HLOOKUP(P$1,$E25:$G25,1,FALSE) -> #N/A | Q25: =HLOOKUP(Q$1,$E25:$G25,1,FALSE) -> #N/A | R25: =HLOOKUP(R$1,$E25:$G25,1,FALSE) -> #N/A | ... AP25: =HLOOKUP(AP$1,$E25:$G25,1,FALSE) -> #N/A
D26: 25 | E26: 26 | F26: 29 | J26: 25 | K26: =HLOOKUP(K$1,$E26:$G26,1,FALSE) -> #N/A | L26: =HLOOKUP(L$1,$E26:$G26,1,FALSE) -> #N/A | M26: =HLOOKUP(M$1,$E26:$G26,1,FALSE) -> #N/A | N26: =HLOOKUP(N$1,$E26:$G26,1,FALSE) -> #N/A | O26: =HLOOKUP(O$1,$E26:$G26,1,FALSE) -> #N/A | P26: =HLOOKUP(P$1,$E26:$G26,1,FALSE) -> #N/A | Q26: =HLOOKUP(Q$1,$E26:$G26,1,FALSE) -> #N/A | R26: =HLOOKUP(R$1,$E26:$G26,1,FALSE) -> #N/A | ... AP26: =HLOOKUP(AP$1,$E26:$G26,1,FALSE) -> #N/A
D27: 26 | E27: 31 | J27: 26 | K27: =HLOOKUP(K$1,$E27:$G27,1,FALSE) -> #N/A | L27: =HLOOKUP(L$1,$E27:$G27,1,FALSE) -> #N/A | M27: =HLOOKUP(M$1,$E27:$G27,1,FALSE) -> #N/A | N27: =HLOOKUP(N$1,$E27:$G27,1,FALSE) -> #N/A | O27: =HLOOKUP(O$1,$E27:$G27,1,FALSE) -> #N/A | P27: =HLOOKUP(P$1,$E27:$G27,1,FALSE) -> #N/A | Q27: =HLOOKUP(Q$1,$E27:$G27,1,FALSE) -> #N/A | R27: =HLOOKUP(R$1,$E27:$G27,1,FALSE) -> #N/A | ... AP27: =HLOOKUP(AP$1,$E27:$G27,1,FALSE) -> #N/A
D28: 27 | E28: 30 | J28: 27 | K28: =HLOOKUP(K$1,$E28:$G28,1,FALSE) -> #N/A | L28: =HLOOKUP(L$1,$E28:$G28,1,FALSE) -> #N/A | M28: =HLOOKUP(M$1,$E28:$G28,1,FALSE) -> #N/A | N28: =HLOOKUP(N$1,$E28:$G28,1,FALSE) -> #N/A | O28: =HLOOKUP(O$1,$E28:$G28,1,FALSE) -> #N/A | P28: =HLOOKUP(P$1,$E28:$G28,1,FALSE) -> #N/A | Q28: =HLOOKUP(Q$1,$E28:$G28,1,FALSE) -> #N/A | R28: =HLOOKUP(R$1,$E28:$G28,1,FALSE) -> #N/A | ... AP28: =HLOOKUP(AP$1,$E28:$G28,1,FALSE) -> #N/A
D29: 28 | E29: 30 | J29: 28 | K29: =HLOOKUP(K$1,$E29:$G29,1,FALSE) -> #N/A | L29: =HLOOKUP(L$1,$E29:$G29,1,FALSE) -> #N/A | M29: =HLOOKUP(M$1,$E29:$G29,1,FALSE) -> #N/A | N29: =HLOOKUP(N$1,$E29:$G29,1,FALSE) -> #N/A | O29: =HLOOKUP(O$1,$E29:$G29,1,FALSE) -> #N/A | P29: =HLOOKUP(P$1,$E29:$G29,1,FALSE) -> #N/A | Q29: =HLOOKUP(Q$1,$E29:$G29,1,FALSE) -> #N/A | R29: =HLOOKUP(R$1,$E29:$G29,1,FALSE) -> #N/A | ... AP29: =HLOOKUP(AP$1,$E29:$G29,1,FALSE) -> #N/A
D30: 29 | E30: 32 | J30: 29 | K30: =HLOOKUP(K$1,$E30:$G30,1,FALSE) -> #N/A | L30: =HLOOKUP(L$1,$E30:$G30,1,FALSE) -> #N/A | M30: =HLOOKUP(M$1,$E30:$G30,1,FALSE) -> #N/A | N30: =HLOOKUP(N$1,$E30:$G30,1,FALSE) -> #N/A | O30: =HLOOKUP(O$1,$E30:$G30,1,FALSE) -> #N/A | P30: =HLOOKUP(P$1,$E30:$G30,1,FALSE) -> #N/A | Q30: =HLOOKUP(Q$1,$E30:$G30,1,FALSE) -> #N/A | R30: =HLOOKUP(R$1,$E30:$G30,1,FALSE) -> #N/A | ... AP30: =HLOOKUP(AP$1,$E30:$G30,1,FALSE) -> 32
D31: 30 | E31: 32 | J31: 30 | K31: =HLOOKUP(K$1,$E31:$G31,1,FALSE) -> #N/A | L31: =HLOOKUP(L$1,$E31:$G31,1,FALSE) -> #N/A | M31: =HLOOKUP(M$1,$E31:$G31,1,FALSE) -> #N/A | N31: =HLOOKUP(N$1,$E31:$G31,1,FALSE) -> #N/A | O31: =HLOOKUP(O$1,$E31:$G31,1,FALSE) -> #N/A | P31: =HLOOKUP(P$1,$E31:$G31,1,FALSE) -> #N/A | Q31: =HLOOKUP(Q$1,$E31:$G31,1,FALSE) -> #N/A | R31: =HLOOKUP(R$1,$E31:$G31,1,FALSE) -> #N/A | ... AP31: =HLOOKUP(AP$1,$E31:$G31,1,FALSE) -> 32
D32: 31 | E32: 32 | J32: 31 | K32: =HLOOKUP(K$1,$E32:$G32,1,FALSE) -> #N/A | L32: =HLOOKUP(L$1,$E32:$G32,1,FALSE) -> #N/A | M32: =HLOOKUP(M$1,$E32:$G32,1,FALSE) -> #N/A | N32: =HLOOKUP(N$1,$E32:$G32,1,FALSE) -> #N/A | O32: =HLOOKUP(O$1,$E32:$G32,1,FALSE) -> #N/A | P32: =HLOOKUP(P$1,$E32:$G32,1,FALSE) -> #N/A | Q32: =HLOOKUP(Q$1,$E32:$G32,1,FALSE) -> #N/A | R32: =HLOOKUP(R$1,$E32:$G32,1,FALSE) -> #N/A | ... AP32: =HLOOKUP(AP$1,$E32:$G32,1,FALSE) -> 32
D33: 32 | J33: 32 | K33: =HLOOKUP(K$1,$E33:$G33,1,FALSE) -> #N/A | L33: =HLOOKUP(L$1,$E33:$G33,1,FALSE) -> #N/A | M33: =HLOOKUP(M$1,$E33:$G33,1,FALSE) -> #N/A | N33: =HLOOKUP(N$1,$E33:$G33,1,FALSE) -> #N/A | O33: =HLOOKUP(O$1,$E33:$G33,1,FALSE) -> #N/A | P33: =HLOOKUP(P$1,$E33:$G33,1,FALSE) -> #N/A | Q33: =HLOOKUP(Q$1,$E33:$G33,1,FALSE) -> #N/A | R33: =HLOOKUP(R$1,$E33:$G33,1,FALSE) -> #N/A | ... AP33: =HLOOKUP(AP$1,$E33:$G33,1,FALSE) -> #N/A
D35: REQUESTS/DURATIONS:
D36: jobnr. | E36: mode | F36: duration | G36: R1 | H36: R2 | I36: R3 | J36: R4 | L36: RESOURCEAVAILABILITIES:
M37: R | N37: 1 | O37: R | P37: 2 | Q37: R | R37: 3 | S37: R | T37: 4
D38: 1 | E38: 1 | F38: 0 | G38: 0 | H38: 0 | I38: 0 | J38: 0 | M38: 13 | N38: 17 | O38: 19 | P38: 14
D39: 2 | E39: 1 | F39: 10 | G39: 8 | H39: 0 | I39: 4 | J39: 4
D40: 3 | E40: 1 | F40: 8 | G40: 6 | H40: 3 | I40: 0 | J40: 7
D41: 4 | E41: 1 | F41: 8 | G41: 7 | H41: 3 | I41: 3 | J41: 8
...

Sheet mm
A1: nkind | L1: {=INDEX($D$4:$D$1048576, (ROW()-1)*3+1)} -> 0 | M1: {=INDEX($D$4:$D$1048576, (ROW()-1)*3+2)} -> 0 | N1: {=INDEX($D$4:$D$1048576, (ROW()-1)*3+1)} -> 0
A2: =MAX(AT4:AT50) -> 2
B3: Task Id | C3: Mode | D3: Duration | E3: r1 | F3: r2 | G3: n1 | H3: n2 | I3: gm1 | J3: gm2 | L3: du | Q3: 1 | R3: 2 | S3: 3 | T3: 4 | U3: 5 | V3: 6 | W3: 7 | X3: 8 | Y3: 9 | Z3: 10 | AB3: renewableResource | AC3: RESOURCEAVAILABILITIES: | AE3: nonrenewableResource | AF3: RESOURCEAVAILABILITIES: | AH3: ReqReRes[i in Activities][m in Modes][k in RenewableResource]
A4: ntask | B4: 1 | C4: 1 | D4: 0 | E4: 0 | F4: 0 | G4: 0 | H4: 0 | I4: 1 | J4: 1 | L4: 0 | M4: 0 | N4: 0 | P4: 1 | Q4: 0 | R4: 1 | S4: 1 | T4: 1 | U4: 0 | V4: 0 | W4: 0 | X4: 0 | Y4: 0 | Z4: 0 | AB4: 1 | AC4: 9 | AE4: 1 | AF4: 41
A5: =MAX(B4:B50) -> 10 | B5: 1 | C5: 2 | D5: 0 | E5: 0 | F5: 0 | G5: 0 | H5: 0 | I5: 0 | J5: 0 | L5: 7 | M5: 8 | N5: 7 | P5: 2 | Q5: 0 | R5: 0 | S5: 0 | T5: 0 | U5: 0 | V5: 0 | W5: 0 | X5: 0 | Y5: 0 | Z5: 0 | AB5: 2 | AC5: 9 | AE5: 2 | AF5: 49 | AH5: activities | AI5: modes | AJ5: RenewableResource | AK5: rrr | AM5: activities | AN5: modes | AO5: nonRenewableResource | AP5: rnr | AR5: activities | AS5: modes | AT5: Kind | AU5: atp | AX5: xim | AY5: 1
B6: 1 | C6: 3 | D6: 0 | E6: 0 | F6: 0 | G6: 0 | H6: 0 | I6: 0 | J6: 0 | L6: 1 | M6: 2 | N6: 1 | P6: 3 | Q6: 0 | R6: 0 | S6: 0 | T6: 0 | U6: 0 | V6: 0 | W6: 1 | X6: 0 | Y6: 0 | Z6: 0 | AF6: =COUNTIF(AI4:AI5,3) -> 0 | AG6: 1 | AH6: 1 | AI6: 1 | AJ6: 1 | AK6: {=_xlfn.TOCOL(E4:F33,1)} -> 0 | AM6: 1 | AN6: 1 | AO6: 1 | AP6: {=_xlfn.TOCOL(G4:H33,0)} -> 0 | AR6: 1 | AS6: 1 | AT6: 1 | AU6: {=_xlfn.TOCOL(I4:J33,0)} -> 1 | AX6: kina | AY6: 0
A7: nmode | B7: 2 | C7: 1 | D7: 7 | E7: 10 | F7: 0 | G7: 10 | H7: 0 | I7: 0 | J7: 1 | L7: 8 | M7: 9 | N7: 8 | P7: 4 | Q7: 0 | R7: 0 | S7: 0 | T7: 0 | U7: 1 | V7: 0 | W7: 1 | X7: 0 | Y7: 0 | Z7: 0 | AF7: =COUNTIF(AI5:AI6,3) -> 0 | AG7: 1 | AH7: 1 | AI7: 1 | AJ7: 2 | AK7: 0 | AM7: 1 | AN7: 1 | AO7: 2 | AP7: 0 | AR7: 1 | AS7: 1 | AT7: 2 | AU7: 1 | AX7: kinb | AY7: 1
A8: =MAX(C4:C50) -> 3 | B8: 2 | C8: 2 | D8: 8 | E8: 6 | F8: 0 | G8: 9 | H8: 0 | I8: 1 | J8: 0 | L8: 1 | M8: 8 | N8: 1 | P8: 5 | Q8: 0 | R8: 0 | S8: 0 | T8: 0 | U8: 0 | V8: 1 | W8: 0 | X8: 0 | Y8: 0 | Z8: 1 | AF8: =COUNTIF(AI6:AI7,3) -> 0 | AG8: =IF(AF8=2,AG7+1,AG7) -> 1 | AH8: 1 | AI8: 2 | AJ8: 1 | AK8: 0 | AM8: 1 | AN8: 2 | AO8: 1 | AP8: 0 | AR8: 1 | AS8: 2 | AT8: 1 | AU8: 0
B9: 2 | C9: 3 | D9: 8 | E9: 3 | F9: 0 | G9: 0 | H9: 5 | I9: 1 | J9: 1 | L9: 5 | M9: 6 | N9: 5 | P9: 6 | Q9: 0 | R9: 0 | S9: 0 | T9: 0 | U9: 0 | V9: 0 | W9: 0 | X9: 1 | Y9: 0 | Z9: 0 | AF9: =COUNTIF(AI7:AI8,3) -> 0 | AG9: =IF(AF9=2,AG8+1,AG8) -> 1 | AH9: 1 | AI9: 2 | AJ9: 2 | AK9: 0 | AM9: 1 | AN9: 2 | AO9: 2 | AP9: 0 | AR9: 1 | AS9: 2 | AT9: 2 | AU9: 0
A10: horizon | B10: 3 | C10: 1 | D10: 1 | E10: 0 | F10: 4 | G10: 0 | H10: 5 | I10: 1 | J10: 1 | L10: 4 | M10: 7 | N10: 4 | P10: 7 | Q10: 0 | R10: 0 | S10: 0 | T10: 0 | U10: 0 | V10: 0 | W10: 0 | X10: 1 | Y10: 0 | Z10: 0 | AF10: =COUNTIF(AI8:AI9,3) -> 0 | AG10: =IF(AF10=2,AG9+1,AG9) -> 1 | AH10: 1 | AI10: 3 | AJ10: 1 | AK10: 0 | AM10: 1 | AN10: 3 | AO10: 1 | AP10: 0 | AR10: 1 | AS10: 3 | AT10: 1 | AU10: 0
A11: =ROUND(SUM(D4:D50)/3,0) -> 47 | B11: 3 | C11: 2 | D11: 2 | E11: 4 | F11: 0 | G11: 0 | H11: 4 | I11: 0 | J11: 1 | L11: 1 | M11: 4 | N11: 1 | P11: 8 | Q11: 0 | R11: 0 | S11: 0 | T11: 0 | U11: 0 | V11: 0 | W11: 0 | X11: 0 | Y11: 1 | Z11: 0 | AF11: =COUNTIF(AI9:AI10,3) -> 1 | AG11: =IF(AF11=2,AG10+1,AG10) -> 1 | AH11: 1 | AI11: 3 | AJ11: 2 | AK11: 0 | AM11: 1 | AN11: 3 | AO11: 2 | AP11: 0 | AR11: 1 | AS11: 3 | AT11: 2 | AU11: 0
B12: 3 | C12: 3 | D12: 3 | E12: 0 | F12: 3 | G12: 0 | H12: 1 | I12: 1 | J12: 0 | L12: 4 | M12: 4 | N12: 4 | P12: 9 | Q12: 0 | R12: 0 | S12: 0 | T12: 0 | U12: 0 | V12: 0 | W12: 0 | X12: 0 | Y12: 0 | Z12: 0 | AF12: =COUNTIF(AI10:AI11,3) -> 2 | AG12: =IF(AF12=2,AG11+1,AG11) -> 2 | AH12: 2 | AI12: 1 | AJ12: 1 | AK12: 10 | AM12: 2 | AN12: 1 | AO12: 1 | AP12: 10 | AR12: 2 | AS12: 1 | AT12: 1 | AU12: 0
A13: nrr | B13: 4 | C13: 1 | D13: 8 | E13: 1 | F13: 0 | G13: 0 | H13: 7 | I13: 1 | J13: 0 | L13: 1 | M13: 0 | N13: 1 | P13: 10 | Q13: 0 | R13: 0 | S13: 0 | T13: 0 | U13: 0 | V13: 0 | W13: 0 | X13: 0 | Y13: 0 | Z13: 0 | AF13: =COUNTIF(AI11:AI12,3) -> 1 | AG13: =IF(AF13=2,AG12+1,AG12) -> 2 | AH13: 2 | AI13: 1 | AJ13: 2 | AK13: 0 | AM13: 2 | AN13: 1 | AO13: 2 | AP13: 0 | AR13: 2 | AS13: 1 | AT13: 2 | AU13: 1
A14: =MAX(AB4:AB50) -> 2 | B14: 4 | C14: 2 | D14: 9 | E14: 1 | F14: 0 | G14: 4 | H14: 0 | I14: 1 | J14: 1 | AF14: =COUNTIF(AI12:AI13,3) -> 0 | AG14: =IF(AF14=2,AG13+1,AG13) -> 2 | AH14: 2 | AI14: 2 | AJ14: 1 | AK14: 6 | AM14: 2 | AN14: 2 | AO14: 1 | AP14: 9 | AR14: 2 | AS14: 2 | AT14: 1 | AU14: 1
B15: 4 | C15: 3 | D15: 10 | E15: 0 | F15: 3 | G15: 0 | H15: 4 | I15: 1 | J15: 0 | AF15: =COUNTIF(AI13:AI14,3) -> 0 | AG15: =IF(AF15=2,AG14+1,AG14) -> 2 | AH15: 2 | AI15: 2 | AJ15: 2 | AK15: 0 | AM15: 2 | AN15: 2 | AO15: 2 | AP15: 0 | AR15: 2 | AS15: 2 | AT15: 2 | AU15: 0
A16: nnrr | B16: 5 | C16: 1 | D16: 1 | E16: 9 | F16: 0 | G16: 0 | H16: 2 | I16: 0 | J16: 1 | AF16: =COUNTIF(AI14:AI15,3) -> 0 | AG16: =IF(AF16=2,AG15+1,AG15) -> 2 | AH16: 2 | AI16: 3 | AJ16: 1 | AK16: 3 | AM16: 2 | AN16: 3 | AO16: 1 | AP16: 0 | AR16: 2 | AS16: 3 | AT16: 1 | AU16: 1
A17: =MAX(AE4:AE50) -> 2 | B17: 5 | C17: 2 | D17: 8 | E17: 6 | F17: 0 | G17: 0 | H17: 2 | I17: 1 | J17: 0 | AF17: =COUNTIF(AI15:AI16,3) -> 1 | AG17: =IF(AF17=2,AG16+1,AG16) -> 2 | AH17: 2 | AI17: 3 | AJ17: 2 | AK17: 0 | AM17: 2 | AN17: 3 | AO17: 2 | AP17: 5 | AR17: 2 | AS17: 3 | AT17: 2 | AU17: 1
B18: 5 | C18: 3 | D18: 9 | E18: 4 | F18: 0 | G18: 0 | H18: 1 | I18: 1 | J18: 1 | AF18: =COUNTIF(AI16:AI17,3) -> 2 | AG18: =IF(AF18=2,AG17+1,AG17) -> 3 | AH18: 3 | AI18: 1 | AJ18: 1 | AK18: 0 | AM18: 3 | AN18: 1 | AO18: 1 | AP18: 0 | AR18: 3 | AS18: 1 | AT18: 1 | AU18: 1
B19: 6 | C19: 1 | D19: 5 | E19: 4 | F19: 0 | G19: 5 | H19: 0 | I19: 1 | J19: 1 | AF19: =COUNTIF(AI17:AI18,3) -> 1 | AG19: =IF(AF19=2,AG18+1,AG18) -> 3 | AH19: 3 | AI19: 1 | AJ19: 2 | AK19: 4 | AM19: 3 | AN19: 1 | AO19: 2 | AP19: 5 | AR19: 3 | AS19: 1 | AT19: 2 | AU19: 1
B20: 6 | C20: 2 | D20: 6 | E20: 3 | F20: 0 | G20: 5 | H20: 0 | I20: 1 | J20: 0 | AF20: =COUNTIF(AI18:AI19,3) -> 0 | AG20: =IF(AF20=2,AG19+1,AG19) -> 3 | AH20: 3 | AI20: 2 | AJ20: 1 | AK20: 4 | AM20: 3 | AN20: 2 | AO20: 1 | AP20: 0 | AR20: 3 | AS20: 2 | AT20: 1 | AU20: 0
B21: 6 | C21: 3 | D21: 7 | E21: 3 | F21: 0 | G21: 0 | H21: 5 | I21: 1 | J21: 0 | AF21: =COUNTIF(AI19:AI20,3) -> 0 | AG21: =IF(AF21=2,AG20+1,AG20) -> 3 | AH21: 3 | AI21: 2 | AJ21: 2 | AK21: 0 | AM21: 3 | AN21: 2 | AO21: 2 | AP21: 4 | AR21: 3 | AS21: 2 | AT21: 2 | AU21: 1
B22: 7 | C22: 1 | D22: 4 | E22: 10 | F22: 0 | G22: 0 | H22: 6 | I22: 1 | J22: 1 | AF22: =COUNTIF(AI20:AI21,3) -> 0 | AG22: =IF(AF22=2,AG21+1,AG21) -> 3 | AH22: 3 | AI22: 3 | AJ22: 1 | AK22: 0 | AM22: 3 | AN22: 3 | AO22: 1 | AP22: 0 | AR22: 3 | AS22: 3 | AT22: 1 | AU22: 1
B23: 7 | C23: 2 | D23: 7 | E23: 7 | F23: 0 | G23: 0 | H23: 6 | I23: 1 | J23: 1 | AF23: =COUNTIF(AI21:AI22,3) -> 1 | AG23: =IF(AF23=2,AG22+1,AG22) -> 3 | AH23: 3 | AI23: 3 | AJ23: 2 | AK23: 3 | AM23: 3 | AN23: 3 | AO23: 2 | AP23: 1 | AR23: 3 | AS23: 3 | AT23: 2 | AU23: 0
B24: 7 | C24: 3 | D24: 10 | E24: 3 | F24: 0 | G24: 10 | H24: 0 | I24: 1 | J24: 1 | AF24: =COUNTIF(AI22:AI23,3) -> 2 | AG24: =IF(AF24=2,AG23+1,AG23) -> 4 | AH24: 4 | AI24: 1 | AJ24: 1 | AK24: 1 | AM24: 4 | AN24: 1 | AO24: 1 | AP24: 0 | AR24: 4 | AS24: 1 | AT24: 1 | AU24: 1
B25: 8 | C25: 1 | D25: 1 | E25: 0 | F25: 7 | G25: 2 | H25: 0 | I25: 1 | J25: 0 | AF25: =COUNTIF(AI23:AI24,3) -> 1 | AG25: =IF(AF25=2,AG24+1,AG24) -> 4 | AH25: 4 | AI25: 1 | AJ25: 2 | AK25: 0 | AM25: 4 | AN25: 1 | AO25: 2 | AP25: 7 | AR25: 4 | AS25: 1 | AT25: 2 | AU25: 0
B26: 8 | C26: 2 | D26: 4 | E26: 0 | F26: 6 | G26: 1 | H26: 0 | I26: 0 | J26: 1 | AF26: =COUNTIF(AI24:AI25,3) -> 0 | AG26: =IF(AF26=2,AG25+1,AG25) -> 4 | AH26: 4 | AI26: 2 | AJ26: 1 | AK26: 1 | AM26: 4 | AN26: 2 | AO26: 1 | AP26: 4 | AR26: 4 | AS26: 2 | AT26: 1 | AU26: 1
B27: 8 | C27: 3 | D27: 7 | E27: 0 | F27: 3 | G27: 0 | H27: 1 | I27: 1 | J27: 1 | AF27: =COUNTIF(AI25:AI26,3) -> 0 | AG27: =IF(AF27=2,AG26+1,AG26) -> 4 | AH27: 4 | AI27: 2 | AJ27: 2 | AK27: 0 | AM27: 4 | AN27: 2 | AO27: 2 | AP27: 0 | AR27: 4 | AS27: 2 | AT27: 2 | AU27: 1
B28: 9 | C28: 1 | D28: 4 | E28: 0 | F28: 4 | G28: 0 | H28: 7 | I28: 1 | J28: 1 | AF28: =COUNTIF(AI26:AI27,3) -> 0 | AG28: =IF(AF28=2,AG27+1,AG27) -> 4 | AH28: 4 | AI28: 3 | AJ28: 1 | AK28: 0 | AM28: 4 | AN28: 3 | AO28: 1 | AP28: 0 | AR28: 4 | AS28: 3 | AT28: 1 | AU28: 1
B29: 9 | C29: 2 | D29: 4 | E29: 6 | F29: 0 | G29: 10 | H29: 0 | I29: 0 | J29: 1 | AF29: =COUNTIF(AI27:AI28,3) -> 1 | AG29: =IF(AF29=2,AG28+1,AG28) -> 4 | AH29: 4 | AI29: 3 | AJ29: 2 | AK29: 3 | AM29: 4 | AN29: 3 | AO29: 2 | AP29: 4 | AR29: 4 | AS29: 3 | AT29: 2 | AU29: 0
... B33: 10 | C33: 3 | D33: 0 | E33: 0 | F33: 0 | G33: 0 | H33: 0 | I33: 0 | J33: 0 | AF33: =COUNTIF(AI31:AI32,3) -> 0 | AG33: =IF(AF33=2,AG32+1,AG32) -> 5 | AH33: 5 | AI33: 2 | AJ33: 2 | AK33: 0 | AM33: 5 | AN33: 2 | AO33: 2 | AP33: 2 | AR33: 5 | AS33: 2 | AT33: 2 | AU33: 0
AF34: =COUNTIF(AI32:AI33,3) -> 0 | AG34: =IF(AF34=2,AG33+1,AG33) -> 5 | AH34: 5 | AI34: 3 | AJ34: 1 | AK34: 4 | AM34: 5 | AN34: 3 | AO34: 1 | AP34: 0 | AR34: 5 | AS34: 3 | AT34: 1 | AU34: 1
AF35: =COUNTIF(AI33:AI34,3) -> 1 | AG35: =IF(AF35=2,AG34+1,AG34) -> 5 | AH35: 5 | AI35: 3 | AJ35: 2 | AK35: 0 | AM35: 5 | AN35: 3 | AO35: 2 | AP35: 1 | AR35: 5 | AS35: 3 | AT35: 2 | AU35: 1
AF36: =COUNTIF(AI34:AI35,3) -> 2 | AG36: =IF(AF36=2,AG35+1,AG35) -> 6 | AH36: 6 | AI36: 1 | AJ36: 1 | AK36: 4 | AM36: 6 | AN36: 1 | AO36: 1 | AP36: 5 | AR36: 6 | AS36: 1 | AT36: 1 | AU36: 1
AF37: =COUNTIF(AI35:AI36,3) -> 1 | AG37: =IF(AF37=2,AG36+1,AG36) -> 6 | AH37: 6 | AI37: 1 | AJ37: 2 | AK37: 0 | AM37: 6 | AN37: 1 | AO37: 2 | AP37: 0 | AR37: 6 | AS37: 1 | AT37: 2 | AU37: 1
AF38: =COUNTIF(AI36:AI37,3) -> 0 | AG38: =IF(AF38=2,AG37+1,AG37) -> 6 | AH38: 6 | AI38: 2 | AJ38: 1 | AK38: 3 | AM38: 6 | AN38: 2 | AO38: 1 | AP38: 5 | AR38: 6 | AS38: 2 | AT38: 1 | AU38: 1
AF39: =COUNTIF(AI37:AI38,3) -> 0 | AG39: =IF(AF39=2,AG38+1,AG38) -> 6 | AH39: 6 | AI39: 2 | AJ39: 2 | AK39: 0 | AM39: 6 | AN39: 2 | AO39: 2 | AP39: 0 | AR39: 6 | AS39: 2 | AT39: 2 | AU39: 0
AF40: =COUNTIF(AI38:AI39,3) -> 0 | AG40: =IF(AF40=2,AG39+1,AG39) -> 6 | AH40: 6 | AI40: 3 | AJ40: 1 | AK40: 3 | AM40: 6 | AN40: 3 | AO40: 1 | AP40: 0 | AR40: 6 | AS40: 3 | AT40: 1 | AU40: 1
AF41: =COUNTIF(AI39:AI40,3) -> 1 | AG41: =IF(AF41=2,AG40+1,AG40) -> 6 | AH41: 6 | AI41: 3 | AJ41: 2 | AK41: 0 | AM41: 6 | AN41: 3 | AO41: 2 | AP41: 5 | AR41: 6 | AS41: 3 | AT41: 2 | AU41: 0
AF42: =COUNTIF(AI40:AI41,3) -> 2 | AG42: =IF(AF42=2,AG41+1,AG41) -> 7 | AH42: 7 | AI42: 1 | AJ42: 1 | AK42: 10 | AM42: 7 | AN42: 1 | AO42: 1 | AP42: 0 | AR42: 7 | AS42: 1 | AT42: 1 | AU42: 1
AF43: =COUNTIF(AI41:AI42,3) -> 1 | AG43: =IF(AF43=2,AG42+1,AG42) -> 7 | AH43: 7 | AI43: 1 | AJ43: 2 | AK43: 0 | AM43: 7 | AN43: 1 | AO43: 2 | AP43: 6 | AR43: 7 | AS43: 1 | AT43: 2 | AU43: 1
...

Sheet c159-2
B1: projects | C1: : | D1: 1
B2: jobs | C2: (incl. | D2: supersource/sink | E2: ): | F2: 18
B3: horizon | C3: : | D3: 120
B4: RESOURCES
C5: - | D5: renewable | E5: : | F5: 2 | G5: R
C6: - | D6: nonrenewable | E6: : | F6: 2 | G6: N
C7: - | D7: doubly | E7: constrained | F7: : | G7: 0 | H7: D
B9: PROJECT | C9: INFORMATION:
B10: pronr. | C10: #jobs | D10: rel.date | E10: duedate | F10: tardcost | G10: MPM-Time | AK10: activities\mode | AL10: 1 | AM10: 2 | AN10: 3 | AQ10: Task Id | AR10: Mode | AS10: Duration | AT10: r1 | AU10: r2 | AV10: n1 | AW10: n2 | AX10: gm | AY10: gm1 | AZ10: gm2
C11: 1 | D11: 16 | E11: 0 | F11: 21 | G11: 2 | H11: 21 | AK11: 1 | AL11: Column1 | AM11: Column2 | AN11: Column3 | AO11: =COUNTIF(AL12:AN12,1) -> 1 | AQ11: 1 | AR11: 1 | AS11: 0 | AT11: 0 | AU11: 0 | AV11: 0 | AW11: 0 | AX11: 3 | AY11: =IF(AX11=3,1,IF(AX11=1,1,0)) -> 1 | AZ11: =IF(AX11=3,1,IF(AX11=2,1,0)) -> 1
AK12: 2 | AL12: 1 | AM12: 2 | AN12: 3 | AO12: =COUNTIF(AL13:AN13,1) -> 1 | AQ12: 2 | AR12: 1 | AS12: 7 | AT12: 10 | AU12: 0 | AV12: 10 | AW12: 0 | AX12: 2 | AY12: =IF(AX12=3,1,IF(AX12=1,1,0)) -> 0 | AZ12: =IF(AX12=3,1,IF(AX12=2,1,0)) -> 1
C13: PRECEDENCE | D13: RELATIONS: | AK13: 3 | AL13: 2 | AM13: 1 | AN13: 3 | AO13: =COUNTIF(AL14:AN14,1) -> 1 | AQ13: 2 | AR13: 2 | AS13: 8 | AT13: 6 | AU13: 0 | AV13: 9 | AW13: 0 | AX13: 1 | AY13: =IF(AX13=3,1,IF(AX13=1,1,0)) -> 1 | AZ13: =IF(AX13=3,1,IF(AX13=2,1,0)) -> 0
C14: jobnr. | D14: #modes | E14: #successors | F14: successors | O14: 1 | P14: 2 | Q14: 3 | R14: 4 | S14: 5 | T14: 6 | U14: 7 | V14: 8 | W14: 9 | X14: 10 | Y14: 11 | Z14: 12 | AA14: 13 | AB14: 14 | AC14: 15 | AD14: 16 | AE14: 17 | AF14: 18 | AK14: 4 | AL14: 3 | AM14: 2 | AN14: 1 | AO14: =COUNTIF(AL15:AN15,1) -> 2 | AQ14: 2 | AR14: 3 | AS14: 8 | AT14: 3 | AU14: 0 | AV14: 0 | AW14: 5 | AX14: 3 | AY14: =IF(AX14=3,1,IF(AX14=1,1,0)) -> 1 | AZ14: =IF(AX14=3,1,IF(AX14=2,1,0)) -> 1
C15: 1 | D15: 1 | E15: 3 | F15: 2 | G15: 3 | H15: 4 | N15: 1 | O15: =HLOOKUP(O$14,$F15:$H15,1,FALSE) -> #N/A | P15: =HLOOKUP(P$14,$F15:$H15,1,FALSE) -> 2 | Q15: =HLOOKUP(Q$14,$F15:$H15,1,FALSE) -> 3 | R15: =HLOOKUP(R$14,$F15:$H15,1,FALSE) -> 4 | S15: =HLOOKUP(S$14,$F15:$H15,1,FALSE) -> #N/A | T15: =HLOOKUP(T$14,$F15:$H15,1,FALSE) -> #N/A | U15: =HLOOKUP(U$14,$F15:$H15,1,FALSE) -> #N/A | V15: =HLOOKUP(V$14,$F15:$H15,1,FALSE) -> #N/A | ... AF15: =HLOOKUP(AF$14,$F15:$H15,1,FALSE) -> #N/A | AK15: 5 | AL15: 1 | AM15: 3 | AN15: 1 | AO15: =COUNTIF(AL16:AN16,1) -> 1 | AQ15: 3 | AR15: 1 | AS15: 1 | AT15: 0 | AU15: 4 | AV15: 0 | AW15: 5 | AX15: 3 | AY15: =IF(AX15=3,1,IF(AX15=1,1,0)) -> 1 | AZ15: =IF(AX15=3,1,IF(AX15=2,1,0)) -> 1
C16: 2 | D16: 3 | E16: 1 | F16: 16 | N16: 2 | O16: =HLOOKUP(O$14,$F16:$H16,1,FALSE) -> #N/A | P16: =HLOOKUP(P$14,$F16:$H16,1,FALSE) -> #N/A | Q16: =HLOOKUP(Q$14,$F16:$H16,1,FALSE) -> #N/A | R16: =HLOOKUP(R$14,$F16:$H16,1,FALSE) -> #N/A | S16: =HLOOKUP(S$14,$F16:$H16,1,FALSE) -> #N/A | T16: =HLOOKUP(T$14,$F16:$H16,1,FALSE) -> #N/A | U16: =HLOOKUP(U$14,$F16:$H16,1,FALSE) -> #N/A | V16: =HLOOKUP(V$14,$F16:$H16,1,FALSE) -> #N/A | ... AF16: =HLOOKUP(AF$14,$F16:$H16,1,FALSE) -> #N/A | AK16: 6 | AL16: 2 | AM16: 1 | AN16: 3 | AO16: =COUNTIF(AL17:AN17,1) -> 2 | AQ16: 3 | AR16: 2 | AS16: 2 | AT16: 4 | AU16: 0 | AV16: 0 | AW16: 4 | AX16: 2 | AY16: =IF(AX16=3,1,IF(AX16=1,1,0)) -> 0 | AZ16: =IF(AX16=3,1,IF(AX16=2,1,0)) -> 1
C17: 3 | D17: 3 | E17: 2 | F17: 7 | G17: 11 | N17: 3 | O17: =HLOOKUP(O$14,$F17:$H17,1,FALSE) -> #N/A | P17: =HLOOKUP(P$14,$F17:$H17,1,FALSE) -> #N/A | Q17: =HLOOKUP(Q$14,$F17:$H17,1,FALSE) -> #N/A | R17: =HLOOKUP(R$14,$F17:$H17,1,FALSE) -> #N/A | S17: =HLOOKUP(S$14,$F17:$H17,1,FALSE) -> #N/A | T17: =HLOOKUP(T$14,$F17:$H17,1,FALSE) -> #N/A | U17: =HLOOKUP(U$14,$F17:$H17,1,FALSE) -> 7 | V17: =HLOOKUP(V$14,$F17:$H17,1,FALSE) -> #N/A | ... AF17: =HLOOKUP(AF$14,$F17:$H17,1,FALSE) -> #N/A | AK17: 7 | AL17: 3 | AM17: 1 | AN17: 1 | AO17: =COUNTIF(AL18:AN18,1) -> 0 | AQ17: 3 | AR17: 3 | AS17: 3 | AT17: 0 | AU17: 3 | AV17: 0 | AW17: 1 | AX17: 1 | AY17: =IF(AX17=3,1,IF(AX17=1,1,0)) -> 1 | AZ17: =IF(AX17=3,1,IF(AX17=2,1,0)) -> 0
C18: 4 | D18: 3 | E18: 3 | F18: 5 | G18: 7 | H18: 12 | N18: 4 | O18: =HLOOKUP(O$14,$F18:$H18,1,FALSE) -> #N/A | P18: =HLOOKUP(P$14,$F18:$H18,1,FALSE) -> #N/A | Q18: =HLOOKUP(Q$14,$F18:$H18,1,FALSE) -> #N/A | R18: =HLOOKUP(R$14,$F18:$H18,1,FALSE) -> #N/A | S18: =HLOOKUP(S$14,$F18:$H18,1,FALSE) -> 5 | T18: =HLOOKUP(T$14,$F18:$H18,1,FALSE) -> #N/A | U18: =HLOOKUP(U$14,$F18:$H18,1,FALSE) -> 7 | V18: =HLOOKUP(V$14,$F18:$H18,1,FALSE) -> #N/A | ... AF18: =HLOOKUP(AF$14,$F18:$H18,1,FALSE) -> #N/A | AK18: 8 | AL18: 3 | AM18: 3 | AN18: 3 | AO18: =COUNTIF(AL19:AN19,1) -> 1 | AQ18: 4 | AR18: 1 | AS18: 8 | AT18: 1 | AU18: 0 | AV18: 0 | AW18: 7 | AX18: 1 | AY18: =IF(AX18=3,1,IF(AX18=1,1,0)) -> 1 | AZ18: =IF(AX18=3,1,IF(AX18=2,1,0)) -> 0
C19: 5 | D19: 3 | E19: 2 | F19: 6 | G19: 10 | N19: 5 | O19: =HLOOKUP(O$14,$F19:$H19,1,FALSE) -> #N/A | P19: =HLOOKUP(P$14,$F19:$H19,1,FALSE) -> #N/A | Q19: =HLOOKUP(Q$14,$F19:$H19,1,FALSE) -> #N/A | R19: =HLOOKUP(R$14,$F19:$H19,1,FALSE) -> #N/A | S19: =HLOOKUP(S$14,$F19:$H19,1,FALSE) -> #N/A | T19: =HLOOKUP(T$14,$F19:$H19,1,FALSE) -> 6 | U19: =HLOOKUP(U$14,$F19:$H19,1,FALSE) -> #N/A | V19: =HLOOKUP(V$14,$F19:$H19,1,FALSE) -> #N/A | ... AF19: =HLOOKUP(AF$14,$F19:$H19,1,FALSE) -> #N/A | AK19: 9 | AL19: 1 | AM19: 2 | AN19: 3 | AO19: =COUNTIF(AL20:AN20,1) -> 1 | AQ19: 4 | AR19: 2 | AS19: 9 | AT19: 1 | AU19: 0 | AV19: 4 | AW19: 0 | AX19: 3 | AY19: =IF(AX19=3,1,IF(AX19=1,1,0)) -> 1 | AZ19: =IF(AX19=3,1,IF(AX19=2,1,0)) -> 1
C20: 6 | D20: 3 | E20: 2 | F20: 8 | G20: 16 | N20: 6 | O20: =HLOOKUP(O$14,$F20:$H20,1,FALSE) -> #N/A | P20: =HLOOKUP(P$14,$F20:$H20,1,FALSE) -> #N/A | Q20: =HLOOKUP(Q$14,$F20:$H20,1,FALSE) -> #N/A | R20: =HLOOKUP(R$14,$F20:$H20,1,FALSE) -> #N/A | S20: =HLOOKUP(S$14,$F20:$H20,1,FALSE) -> #N/A | T20: =HLOOKUP(T$14,$F20:$H20,1,FALSE) -> #N/A | U20: =HLOOKUP(U$14,$F20:$H20,1,FALSE) -> #N/A | V20: =HLOOKUP(V$14,$F20:$H20,1,FALSE) -> 8 | ... AF20: =HLOOKUP(AF$14,$F20:$H20,1,FALSE) -> #N/A | AK20: 10 | AL20: 3 | AM20: 2 | AN20: 1 | AO20: =COUNTIF(AL21:AN21,1) -> 1 | AQ20: 4 | AR20: 3 | AS20: 10 | AT20: 0 | AU20: 3 | AV20: 0 | AW20: 4 | AX20: 1 | AY20: =IF(AX20=3,1,IF(AX20=1,1,0)) -> 1 | AZ20: =IF(AX20=3,1,IF(AX20=2,1,0)) -> 0
C21: 7 | D21: 3 | E21: 1 | F21: 8 | N21: 7 | O21: =HLOOKUP(O$14,$F21:$H21,1,FALSE) -> #N/A | P21: =HLOOKUP(P$14,$F21:$H21,1,FALSE) -> #N/A | Q21: =HLOOKUP(Q$14,$F21:$H21,1,FALSE) -> #N/A | R21: =HLOOKUP(R$14,$F21:$H21,1,FALSE) -> #N/A | S21: =HLOOKUP(S$14,$F21:$H21,1,FALSE) -> #N/A | T21: =HLOOKUP(T$14,$F21:$H21,1,FALSE) -> #N/A | U21: =HLOOKUP(U$14,$F21:$H21,1,FALSE) -> #N/A | V21: =HLOOKUP(V$14,$F21:$H21,1,FALSE) -> 8 | ... AF21: =HLOOKUP(AF$14,$F21:$H21,1,FALSE) -> #N/A | AK21: 11 | AL21: 2 | AM21: 3 | AN21: 1 | AO21: =COUNTIF(AL22:AN22,1) -> 2 | AQ21: 5 | AR21: 1 | AS21: 1 | AT21: 9 | AU21: 0 | AV21: 0 | AW21: 2 | AX21: 2 | AY21: =IF(AX21=3,1,IF(AX21=1,1,0)) -> 0 | AZ21: =IF(AX21=3,1,IF(AX21=2,1,0)) -> 1
C22: 8 | D22: 3 | E22: 1 | F22: 9 | N22: 8 | O22: =HLOOKUP(O$14,$F22:$H22,1,FALSE) -> #N/A | P22: =HLOOKUP(P$14,$F22:$H22,1,FALSE) -> #N/A | Q22: =HLOOKUP(Q$14,$F22:$H22,1,FALSE) -> #N/A | R22: =HLOOKUP(R$14,$F22:$H22,1,FALSE) -> #N/A | S22: =HLOOKUP(S$14,$F22:$H22,1,FALSE) -> #N/A | T22: =HLOOKUP(T$14,$F22:$H22,1,FALSE) -> #N/A | U22: =HLOOKUP(U$14,$F22:$H22,1,FALSE) -> #N/A | V22: =HLOOKUP(V$14,$F22:$H22,1,FALSE) -> #N/A | ... AF22: =HLOOKUP(AF$14,$F22:$H22,1,FALSE) -> #N/A | AK22: 12 | AL22: 3 | AM22: 1 | AN22: 1 | AO22: =COUNTIF(AL23:AN23,1) -> 1 | AQ22: 5 | AR22: 2 | AS22: 8 | AT22: 6 | AU22: 0 | AV22: 0 | AW22: 2 | AX22: 1 | AY22: =IF(AX22=3,1,IF(AX22=1,1,0)) -> 1 | AZ22: =IF(AX22=3,1,IF(AX22=2,1,0)) -> 0
C23: 9 | D23: 3 | E23: 1 | F23: 14 | N23: 9 | O23: =HLOOKUP(O$14,$F23:$H23,1,FALSE) -> #N/A | P23: =HLOOKUP(P$14,$F23:$H23,1,FALSE) -> #N/A | Q23: =HLOOKUP(Q$14,$F23:$H23,1,FALSE) -> #N/A | R23: =HLOOKUP(R$14,$F23:$H23,1,FALSE) -> #N/A | S23: =HLOOKUP(S$14,$F23:$H23,1,FALSE) -> #N/A | T23: =HLOOKUP(T$14,$F23:$H23,1,FALSE) -> #N/A | U23: =HLOOKUP(U$14,$F23:$H23,1,FALSE) -> #N/A | V23: =HLOOKUP(V$14,$F23:$H23,1,FALSE) -> #N/A | ... AF23: =HLOOKUP(AF$14,$F23:$H23,1,FALSE) -> #N/A | AK23: 13 | AL23: 1 | AM23: 3 | AN23: 2 | AO23: =COUNTIF(AL24:AN24,1) -> 1 | AQ23: 5 | AR23: 3 | AS23: 9 | AT23: 4 | AU23: 0 | AV23: 0 | AW23: 1 | AX23: 3 | AY23: =IF(AX23=3,1,IF(AX23=1,1,0)) -> 1 | AZ23: =IF(AX23=3,1,IF(AX23=2,1,0)) -> 1
C24: 10 | D24: 3 | E24: 3 | F24: 13 | G24: 15 | H24: 17 | N24: 10 | O24: =HLOOKUP(O$14,$F24:$H24,1,FALSE) -> #N/A | P24: =HLOOKUP(P$14,$F24:$H24,1,FALSE) -> #N/A | Q24: =HLOOKUP(Q$14,$F24:$H24,1,FALSE) -> #N/A | R24: =HLOOKUP(R$14,$F24:$H24,1,FALSE) -> #N/A | S24: =HLOOKUP(S$14,$F24:$H24,1,FALSE) -> #N/A | T24: =HLOOKUP(T$14,$F24:$H24,1,FALSE) -> #N/A | U24: =HLOOKUP(U$14,$F24:$H24,1,FALSE) -> #N/A | V24: =HLOOKUP(V$14,$F24:$H24,1,FALSE) -> #N/A | ... AF24: =HLOOKUP(AF$14,$F24:$H24,1,FALSE) -> #N/A | AK24: 14 | AL24: 1 | AM24: 3 | AN24: 2 | AO24: =COUNTIF(AL25:AN25,1) -> 1 | AQ24: 6 | AR24: 1 | AS24: 5 | AT24: 4 | AU24: 0 | AV24: 5 | AW24: 0 | AX24: 3 | AY24: =IF(AX24=3,1,IF(AX24=1,1,0)) -> 1 | AZ24: =IF(AX24=3,1,IF(AX24=2,1,0)) -> 1
C25: 11 | D25: 3 | E25: 1 | F25: 13 | N25: 11 | O25: =HLOOKUP(O$14,$F25:$H25,1,FALSE) -> #N/A | P25: =HLOOKUP(P$14,$F25:$H25,1,FALSE) -> #N/A | Q25: =HLOOKUP(Q$14,$F25:$H25,1,FALSE) -> #N/A | R25: =HLOOKUP(R$14,$F25:$H25,1,FALSE) -> #N/A | S25: =HLOOKUP(S$14,$F25:$H25,1,FALSE) -> #N/A | T25: =HLOOKUP(T$14,$F25:$H25,1,FALSE) -> #N/A | U25: =HLOOKUP(U$14,$F25:$H25,1,FALSE) -> #N/A | V25: =HLOOKUP(V$14,$F25:$H25,1,FALSE) -> #N/A | ... AF25: =HLOOKUP(AF$14,$F25:$H25,1,FALSE) -> #N/A | AK25: 15 | AL25: 1 | AM25: 2 | AN25: 3 | AO25: =COUNTIF(AL26:AN26,1) -> 1 | AQ25: 6 | AR25: 2 | AS25: 6 | AT25: 3 | AU25: 0 | AV25: 5 | AW25: 0 | AX25: 1 | AY25: =IF(AX25=3,1,IF(AX25=1,1,0)) -> 1 | AZ25: =IF(AX25=3,1,IF(AX25=2,1,0)) -> 0
